Workbook

Sheet メニュー原価一覧
A1: RAKU SPA 1010 神田 メニュー別 原価・粗利益一覧
A2: メニュー構成：メニューリスト「250508更新」準拠（価格はメニュー表2506 PDF）／原価：2024 GMレシピ
C3: 改訂前 | D3: 改訂後
A4: 消費税率 | C4: 0.1 | D4: 0.1 | F4: 値上げ品数 | G4: =COUNTIF(N11:N159,">0") -> 125
A5: メニュー数 | C5: =COUNTA(D11:D159) -> 149 | D5: =COUNTA(D11:D159) -> 149 | F5: 平均値上げ幅（税込） | G5: =IFERROR(AVERAGEIF(N11:N159,">0"),"") -> 29.52
A6: 平均原価率 | C6: =IFERROR(AVERAGEIF(G11:G159,">0",H11:H159),"") -> 0.28549818 | D6: =IFERROR(AVERAGEIF(G11:G159,">0",L11:L159),"") -> 0.27575208 | F6: 平均値上げ率 | G6: =IFERROR(SUMPRODUCT((N11:N159>0)*(J11:J159/E11:E159-1))/G4,"") -> 0.040837914
A7: 平均粗利益 | C7: =IFERROR(AVERAGEIF(G11:G159,">0",I11:I159),"") -> 516.42248 | D7: =IFERROR(AVERAGEIF(G11:G159,">0",M11:M159),"") -> 539.07316
A8: 原価未登録 | C8: =COUNTA(D11:D159)-COUNTIF(G11:G159,">0") -> 3
J9: 値上げ→
A10: No. | B10: 区分 | C10: 分類 | D10: メニュー名 | E10: 税込価格 | F10: 税抜価格 | G10: 原価（税抜）✎入力 | H10: 原価率 | I10: 粗利益 | J10: 税込価格✎入力 | K10: 税抜価格 | L10: 原価率 | M10: 粗利益 | N10: 価格差（税込） | O10: 備考
A11: 1 | B11: ドリンク | C11: ビール | D11: アサヒスーパードライ（パイントグラス） | E11: 855 | F11: =IF(E11="","",ROUND(E11/(1+$C$4),0)) -> 777 | G11: 284.4 | H11: =IF(OR(F11="",F11=0,G11=""),"",G11/F11) -> 0.36602317 | I11: =IF(OR(F11="",G11=""),"",F11-G11) -> 492.6 | J11: 855 | K11: =IF(J11="","",ROUND(J11/(1+$D$4),0)) -> 777 | L11: =IF(OR(K11="",K11=0,G11=""),"",G11/K11) -> 0.36602317 | M11: =IF(OR(K11="",G11=""),"",K11-G11) -> 492.6 | N11: =J11-E11 -> 0
A12: 2 | B12: ドリンク | C12: ビール | D12: マルエフ | E12: 855 | F12: =IF(E12="","",ROUND(E12/(1+$C$4),0)) -> 777 | G12: 307.2 | H12: =IF(OR(F12="",F12=0,G12=""),"",G12/F12) -> 0.3953668 | I12: =IF(OR(F12="",G12=""),"",F12-G12) -> 469.8 | J12: 855 | K12: =IF(J12="","",ROUND(J12/(1+$D$4),0)) -> 777 | L12: =IF(OR(K12="",K12=0,G12=""),"",G12/K12) -> 0.3953668 | M12: =IF(OR(K12="",G12=""),"",K12-G12) -> 469.8 | N12: =J12-E12 -> 0 | O12: レシピなし／原価未登録
A13: 3 | B13: ドリンク | C13: ビール | D13: 熟撰 | E13: 855 | F13: =IF(E13="","",ROUND(E13/(1+$C$4),0)) -> 777 | G13: 321.7 | H13: =IF(OR(F13="",F13=0,G13=""),"",G13/F13) -> 0.41402831 | I13: =IF(OR(F13="",G13=""),"",F13-G13) -> 455.3 | J13: 855 | K13: =IF(J13="","",ROUND(J13/(1+$D$4),0)) -> 777 | L13: =IF(OR(K13="",K13=0,G13=""),"",G13/K13) -> 0.41402831 | M13: =IF(OR(K13="",G13=""),"",K13-G13) -> 455.3 | N13: =J13-E13 -> 0 | O13: レシピなし／原価未登録
A14: 4 | B14: ドリンク | C14: ビール | D14: 黒生 | E14: 855 | F14: =IF(E14="","",ROUND(E14/(1+$C$4),0)) -> 777 | G14: 307.2 | H14: =IF(OR(F14="",F14=0,G14=""),"",G14/F14) -> 0.3953668 | I14: =IF(OR(F14="",G14=""),"",F14-G14) -> 469.8 | J14: 855 | K14: =IF(J14="","",ROUND(J14/(1+$D$4),0)) -> 777 | L14: =IF(OR(K14="",K14=0,G14=""),"",G14/K14) -> 0.3953668 | M14: =IF(OR(K14="",G14=""),"",K14-G14) -> 469.8 | N14: =J14-E14 -> 0 | O14: レシピなし／原価未登録
A15: 5 | B15: ドリンク | C15: ビール | D15: 1010JUGビール（800ml） | E15: 1023 | F15: =IF(E15="","",ROUND(E15/(1+$C$4),0)) -> 930 | G15: 568.8 | H15: =IF(OR(F15="",F15=0,G15=""),"",G15/F15) -> 0.6116129 | I15: =IF(OR(F15="",G15=""),"",F15-G15) -> 361.2 | J15: 1353 | K15: =IF(J15="","",ROUND(J15/(1+$D$4),0)) -> 1230 | L15: =IF(OR(K15="",K15=0,G15=""),"",G15/K15) -> 0.46243902 | M15: =IF(OR(K15="",G15=""),"",K15-G15) -> 661.2 | N15: =J15-E15 -> 330 | O15: レシピなし／原価未登録
A16: 6 | B16: ドリンク | C16: ビール | D16: ペローニ | E16: 968 | F16: =IF(E16="","",ROUND(E16/(1+$C$4),0)) -> 880 | G16: 310 | H16: =IF(OR(F16="",F16=0,G16=""),"",G16/F16) -> 0.35227273 | I16: =IF(OR(F16="",G16=""),"",F16-G16) -> 570 | J16: 988 | K16: =IF(J16="","",ROUND(J16/(1+$D$4),0)) -> 898 | L16: =IF(OR(K16="",K16=0,G16=""),"",G16/K16) -> 0.34521158 | M16: =IF(OR(K16="",G16=""),"",K16-G16) -> 588 | N16: =J16-E16 -> 20
A17: 7 | B17: ドリンク | C17: ビール | D17: カールスバーグ | E17: 968 | F17: =IF(E17="","",ROUND(E17/(1+$C$4),0)) -> 880 | G17: 215 | H17: =IF(OR(F17="",F17=0,G17=""),"",G17/F17) -> 0.24431818 | I17: =IF(OR(F17="",G17=""),"",F17-G17) -> 665 | J17: 988 | K17: =IF(J17="","",ROUND(J17/(1+$D$4),0)) -> 898 | L17: =IF(OR(K17="",K17=0,G17=""),"",G17/K17) -> 0.23942094 | M17: =IF(OR(K17="",G17=""),"",K17-G17) -> 683 | N17: =J17-E17 -> 20
A18: 8 | B18: ドリンク | C18: ビール | D18: ピルスナー・ウルケル | E18: 968 | F18: =IF(E18="","",ROUND(E18/(1+$C$4),0)) -> 880 | G18: 296 | H18: =IF(OR(F18="",F18=0,G18=""),"",G18/F18) -> 0.33636364 | I18: =IF(OR(F18="",G18=""),"",F18-G18) -> 584 | J18: 988 | K18: =IF(J18="","",ROUND(J18/(1+$D$4),0)) -> 898 | L18: =IF(OR(K18="",K18=0,G18=""),"",G18/K18) -> 0.32962138 | M18: =IF(OR(K18="",G18=""),"",K18-G18) -> 602 | N18: =J18-E18 -> 20
A19: 9 | B19: ドリンク | C19: ビール | D19: アサヒドライゼロ（ノンアル） | E19: 583 | F19: =IF(E19="","",ROUND(E19/(1+$C$4),0)) -> 530 | G19: 169.7 | H19: =IF(OR(F19="",F19=0,G19=""),"",G19/F19) -> 0.32018868 | I19: =IF(OR(F19="",G19=""),"",F19-G19) -> 360.3 | J19: 638 | K19: =IF(J19="","",ROUND(J19/(1+$D$4),0)) -> 580 | L19: =IF(OR(K19="",K19=0,G19=""),"",G19/K19) -> 0.29258621 | M19: =IF(OR(K19="",G19=""),"",K19-G19) -> 410.3 | N19: =J19-E19 -> 55 | O19: レシピなし／原価未登録
A20: 10 | B20: ドリンク | C20: ハイボール | D20: ハイボール | E20: 748 | F20: =IF(E20="","",ROUND(E20/(1+$C$4),0)) -> 680 | G20: 53.5 | H20: =IF(OR(F20="",F20=0,G20=""),"",G20/F20) -> 0.078676471 | I20: =IF(OR(F20="",G20=""),"",F20-G20) -> 626.5 | J20: 748 | K20: =IF(J20="","",ROUND(J20/(1+$D$4),0)) -> 680 | L20: =IF(OR(K20="",K20=0,G20=""),"",G20/K20) -> 0.078676471 | M20: =IF(OR(K20="",G20=""),"",K20-G20) -> 626.5 | N20: =J20-E20 -> 0 | O20: レギュラー748／大容量1,023。レシピ名「1010JUGハイボール」
A21: 11 | B21: ドリンク | C21: ハイボール | D21: コークハイ | E21: 748 | F21: =IF(E21="","",ROUND(E21/(1+$C$4),0)) -> 680 | G21: 172 | H21: =IF(OR(F21="",F21=0,G21=""),"",G21/F21) -> 0.25294118 | I21: =IF(OR(F21="",G21=""),"",F21-G21) -> 508 | J21: 748 | K21: =IF(J21="","",ROUND(J21/(1+$D$4),0)) -> 680 | L21: =IF(OR(K21="",K21=0,G21=""),"",G21/K21) -> 0.25294118 | M21: =IF(OR(K21="",G21=""),"",K21-G21) -> 508 | N21: =J21-E21 -> 0 | O21: レギュラー748／大容量1,023
A22: 12 | B22: ドリンク | C22: ハイボール | D22: ジンジャーハイ | E22: 748 | F22: =IF(E22="","",ROUND(E22/(1+$C$4),0)) -> 680 | G22: 226.2 | H22: =IF(OR(F22="",F22=0,G22=""),"",G22/F22) -> 0.33264706 | I22: =IF(OR(F22="",G22=""),"",F22-G22) -> 453.8 | J22: 748 | K22: =IF(J22="","",ROUND(J22/(1+$D$4),0)) -> 680 | L22: =IF(OR(K22="",K22=0,G22=""),"",G22/K22) -> 0.33264706 | M22: =IF(OR(K22="",G22=""),"",K22-G22) -> 453.8 | N22: =J22-E22 -> 0 | O22: レギュラー748／大容量1,023
A23: 13 | B23: ドリンク | C23: ハイボール | D23: むぎハイ | E23: 748 | F23: =IF(E23="","",ROUND(E23/(1+$C$4),0)) -> 680 | G23: 149.1 | H23: =IF(OR(F23="",F23=0,G23=""),"",G23/F23) -> 0.21926471 | I23: =IF(OR(F23="",G23=""),"",F23-G23) -> 530.9 | J23: 748 | K23: =IF(J23="","",ROUND(J23/(1+$D$4),0)) -> 680 | L23: =IF(OR(K23="",K23=0,G23=""),"",G23/K23) -> 0.21926471 | M23: =IF(OR(K23="",G23=""),"",K23-G23) -> 530.9 | N23: =J23-E23 -> 0 | O23: レギュラー748／大容量1,023
A24: 14 | B24: ドリンク | C24: ハイボール | D24: いもハイ | E24: 748 | F24: =IF(E24="","",ROUND(E24/(1+$C$4),0)) -> 680 | G24: 124.1 | H24: =IF(OR(F24="",F24=0,G24=""),"",G24/F24) -> 0.1825 | I24: =IF(OR(F24="",G24=""),"",F24-G24) -> 555.9 | J24: 748 | K24: =IF(J24="","",ROUND(J24/(1+$D$4),0)) -> 680 | L24: =IF(OR(K24="",K24=0,G24=""),"",G24/K24) -> 0.1825 | M24: =IF(OR(K24="",G24=""),"",K24-G24) -> 555.9 | N24: =J24-E24 -> 0 | O24: レギュラー748／大容量1,023
A25: 15 | B25: ドリンク | C25: サワー | D25: マンゴーサワー | E25: 638 | F25: =IF(E25="","",ROUND(E25/(1+$C$4),0)) -> 580 | G25: 133.6 | H25: =IF(OR(F25="",F25=0,G25=""),"",G25/F25) -> 0.23034483 | I25: =IF(OR(F25="",G25=""),"",F25-G25) -> 446.4 | J25: 638 | K25: =IF(J25="","",ROUND(J25/(1+$D$4),0)) -> 580 | L25: =IF(OR(K25="",K25=0,G25=""),"",G25/K25) -> 0.23034483 | M25: =IF(OR(K25="",G25=""),"",K25-G25) -> 446.4 | N25: =J25-E25 -> 0
A26: 16 | B26: ドリンク | C26: サワー | D26: いちごサワー | E26: 638 | F26: =IF(E26="","",ROUND(E26/(1+$C$4),0)) -> 580 | G26: 121.1 | H26: =IF(OR(F26="",F26=0,G26=""),"",G26/F26) -> 0.2087931 | I26: =IF(OR(F26="",G26=""),"",F26-G26) -> 458.9 | J26: 638 | K26: =IF(J26="","",ROUND(J26/(1+$D$4),0)) -> 580 | L26: =IF(OR(K26="",K26=0,G26=""),"",G26/K26) -> 0.2087931 | M26: =IF(OR(K26="",G26=""),"",K26-G26) -> 458.9 | N26: =J26-E26 -> 0 | O26: レシピなし／原価未登録
A27: 17 | B27: ドリンク | C27: サワー | D27: カルピスサワー | E27: 638 | F27: =IF(E27="","",ROUND(E27/(1+$C$4),0)) -> 580 | G27: 89.3 | H27: =IF(OR(F27="",F27=0,G27=""),"",G27/F27) -> 0.15396552 | I27: =IF(OR(F27="",G27=""),"",F27-G27) -> 490.7 | J27: 638 | K27: =IF(J27="","",ROUND(J27/(1+$D$4),0)) -> 580 | L27: =IF(OR(K27="",K27=0,G27=""),"",G27/K27) -> 0.15396552 | M27: =IF(OR(K27="",G27=""),"",K27-G27) -> 490.7 | N27: =J27-E27 -> 0
A28: 18 | B28: ドリンク | C28: サワー | D28: ウーロンハイ | E28: 638 | F28: =IF(E28="","",ROUND(E28/(1+$C$4),0)) -> 580 | G28: 55.3 | H28: =IF(OR(F28="",F28=0,G28=""),"",G28/F28) -> 0.095344828 | I28: =IF(OR(F28="",G28=""),"",F28-G28) -> 524.7 | J28: 638 | K28: =IF(J28="","",ROUND(J28/(1+$D$4),0)) -> 580 | L28: =IF(OR(K28="",K28=0,G28=""),"",G28/K28) -> 0.095344828 | M28: =IF(OR(K28="",G28=""),"",K28-G28) -> 524.7 | N28: =J28-E28 -> 0 | O28: レシピなし／原価未登録
A29: 19 | B29: ドリンク | C29: サワー | D29: 匠の深絞りレモンサワー | E29: 638 | F29: =IF(E29="","",ROUND(E29/(1+$C$4),0)) -> 580 | G29: 76.42885 | H29: =IF(OR(F29="",F29=0,G29=""),"",G29/F29) -> 0.13177388 | I29: =IF(OR(F29="",G29=""),"",F29-G29) -> 503.57115 | J29: 638 | K29: =IF(J29="","",ROUND(J29/(1+$D$4),0)) -> 580 | L29: =IF(OR(K29="",K29=0,G29=""),"",G29/K29) -> 0.13177388 | M29: =IF(OR(K29="",G29=""),"",K29-G29) -> 503.57115 | N29: =J29-E29 -> 0
A30: 20 | B30: ドリンク | C30: サワー | D30: シチリアレモンサワー | E30: 638 | F30: =IF(E30="","",ROUND(E30/(1+$C$4),0)) -> 580 | G30: 80.4 | H30: =IF(OR(F30="",F30=0,G30=""),"",G30/F30) -> 0.13862069 | I30: =IF(OR(F30="",G30=""),"",F30-G30) -> 499.6 | J30: 638 | K30: =IF(J30="","",ROUND(J30/(1+$D$4),0)) -> 580 | L30: =IF(OR(K30="",K30=0,G30=""),"",G30/K30) -> 0.13862069 | M30: =IF(OR(K30="",G30=""),"",K30-G30) -> 499.6 | N30: =J30-E30 -> 0
A31: 21 | B31: ドリンク | C31: サワー | D31: 塩ライチサワー | E31: 638 | F31: =IF(E31="","",ROUND(E31/(1+$C$4),0)) -> 580 | G31: 81.8 | H31: =IF(OR(F31="",F31=0,G31=""),"",G31/F31) -> 0.14103448 | I31: =IF(OR(F31="",G31=""),"",F31-G31) -> 498.2 | J31: 638 | K31: =IF(J31="","",ROUND(J31/(1+$D$4),0)) -> 580 | L31: =IF(OR(K31="",K31=0,G31=""),"",G31/K31) -> 0.14103448 | M31: =IF(OR(K31="",G31=""),"",K31-G31) -> 498.2 | N31: =J31-E31 -> 0 | O31: レシピなし／原価未登録
A32: 22 | B32: ドリンク | C32: サワー | D32: 塩レモンサワー | E32: 638 | F32: =IF(E32="","",ROUND(E32/(1+$C$4),0)) -> 580 | G32: 81.8 | H32: =IF(OR(F32="",F32=0,G32=""),"",G32/F32) -> 0.14103448 | I32: =IF(OR(F32="",G32=""),"",F32-G32) -> 498.2 | J32: 638 | K32: =IF(J32="","",ROUND(J32/(1+$D$4),0)) -> 580 | L32: =IF(OR(K32="",K32=0,G32=""),"",G32/K32) -> 0.14103448 | M32: =IF(OR(K32="",G32=""),"",K32-G32) -> 498.2 | N32: =J32-E32 -> 0 | O32: レシピなし／原価未登録
A33: 23 | B33: ドリンク | C33: サワー | D33: 塩オレンジサワー | E33: 638 | F33: =IF(E33="","",ROUND(E33/(1+$C$4),0)) -> 580 | G33: 80.4 | H33: =IF(OR(F33="",F33=0,G33=""),"",G33/F33) -> 0.13862069 | I33: =IF(OR(F33="",G33=""),"",F33-G33) -> 499.6 | J33: 638 | K33: =IF(J33="","",ROUND(J33/(1+$D$4),0)) -> 580 | L33: =IF(OR(K33="",K33=0,G33=""),"",G33/K33) -> 0.13862069 | M33: =IF(OR(K33="",G33=""),"",K33-G33) -> 499.6 | N33: =J33-E33 -> 0 | O33: レシピなし／原価未登録
A34: 24 | B34: ドリンク | C34: カクテル・蒸留酒・焼酎 | D34: カシスオレンジ | E34: 638 | F34: =IF(E34="","",ROUND(E34/(1+$C$4),0)) -> 580 | G34: 243.6 | H34: =IF(OR(F34="",F34=0,G34=""),"",G34/F34) -> 0.42 | I34: =IF(OR(F34="",G34=""),"",F34-G34) -> 336.4 | J34: 638 | K34: =IF(J34="","",ROUND(J34/(1+$D$4),0)) -> 580 | L34: =IF(OR(K34="",K34=0,G34=""),"",G34/K34) -> 0.42 | M34: =IF(OR(K34="",G34=""),"",K34-G34) -> 336.4 | N34: =J34-E34 -> 0
A35: 25 | B35: ドリンク | C35: カクテル・蒸留酒・焼酎 | D35: カシスソーダ | E35: 638 | F35: =IF(E35="","",ROUND(E35/(1+$C$4),0)) -> 580 | G35: 91 | H35: =IF(OR(F35="",F35=0,G35=""),"",G35/F35) -> 0.15689655 | I35: =IF(OR(F35="",G35=""),"",F35-G35) -> 489 | J35: 658 | K35: =IF(J35="","",ROUND(J35/(1+$D$4),0)) -> 598 | L35: =IF(OR(K35="",K35=0,G35=""),"",G35/K35) -> 0.15217391 | M35: =IF(OR(K35="",G35=""),"",K35-G35) -> 507 | N35: =J35-E35 -> 20
A36: 26 | B36: ドリンク | C36: カクテル・蒸留酒・焼酎 | D36: フォション大人のミルクティー | E36: 638 | F36: =IF(E36="","",ROUND(E36/(1+$C$4),0)) -> 580 | G36: 139.1 | H36: =IF(OR(F36="",F36=0,G36=""),"",G36/F36) -> 0.23982759 | I36: =IF(OR(F36="",G36=""),"",F36-G36) -> 440.9 | J36: 658 | K36: =IF(J36="","",ROUND(J36/(1+$D$4),0)) -> 598 | L36: =IF(OR(K36="",K36=0,G36=""),"",G36/K36) -> 0.2326087 | M36: =IF(OR(K36="",G36=""),"",K36-G36) -> 458.9 | N36: =J36-E36 -> 20
A37: 27 | B37: ドリンク | C37: カクテル・蒸留酒・焼酎 | D37: モスコミュール | E37: 638 | F37: =IF(E37="","",ROUND(E37/(1+$C$4),0)) -> 580 | G37: 116.2 | H37: =IF(OR(F37="",F37=0,G37=""),"",G37/F37) -> 0.20034483 | I37: =IF(OR(F37="",G37=""),"",F37-G37) -> 463.8 | J37: 658 | K37: =IF(J37="","",ROUND(J37/(1+$D$4),0)) -> 598 | L37: =IF(OR(K37="",K37=0,G37=""),"",G37/K37) -> 0.19431438 | M37: =IF(OR(K37="",G37=""),"",K37-G37) -> 481.8 | N37: =J37-E37 -> 20
A38: 28 | B38: ドリンク | C38: カクテル・蒸留酒・焼酎 | D38: ウィルキンソン ジン（ソーダ割） | E38: 638 | F38: =IF(E38="","",ROUND(E38/(1+$C$4),0)) -> 580 | G38: 49.579643 | H38: =IF(OR(F38="",F38=0,G38=""),"",G38/F38) -> 0.085482144 | I38: =IF(OR(F38="",G38=""),"",F38-G38) -> 530.42036 | J38: 658 | K38: =IF(J38="","",ROUND(J38/(1+$D$4),0)) -> 598 | L38: =IF(OR(K38="",K38=0,G38=""),"",G38/K38) -> 0.082909103 | M38: =IF(OR(K38="",G38=""),"",K38-G38) -> 548.42036 | N38: =J38-E38 -> 20
A39: 29 | B39: ドリンク | C39: カクテル・蒸留酒・焼酎 | D39: ウィルキンソン ウォッカ（ソーダ割） | E39: 638 | F39: =IF(E39="","",ROUND(E39/(1+$C$4),0)) -> 580 | G39: 49.579643 | H39: =IF(OR(F39="",F39=0,G39=""),"",G39/F39) -> 0.085482144 | I39: =IF(OR(F39="",G39=""),"",F39-G39) -> 530.42036 | J39: 658 | K39: =IF(J39="","",ROUND(J39/(1+$D$4),0)) -> 598 | L39: =IF(OR(K39="",K39=0,G39=""),"",G39/K39) -> 0.082909103 | M39: =IF(OR(K39="",G39=""),"",K39-G39) -> 548.42036 | N39: =J39-E39 -> 20
A40: 30 | B40: ドリンク | C40: カクテル・蒸留酒・焼酎 | D40: 麦焼酎 | E40: 638 | F40: =IF(E40="","",ROUND(E40/(1+$C$4),0)) -> 580 | G40: 78.8 | H40: =IF(OR(F40="",F40=0,G40=""),"",G40/F40) -> 0.13586207 | I40: =IF(OR(F40="",G40=""),"",F40-G40) -> 501.2 | J40: 658 | K40: =IF(J40="","",ROUND(J40/(1+$D$4),0)) -> 598 | L40: =IF(OR(K40="",K40=0,G40=""),"",G40/K40) -> 0.13177258 | M40: =IF(OR(K40="",G40=""),"",K40-G40) -> 519.2 | N40: =J40-E40 -> 20 | O40: ソーダ割・水割り・ロック
...

Sheet 分類別サマリー
A1: 分類別サマリー（一覧シートの原価を変更すると自動更新）
A3: 区分 | B3: 分類 | C3: 品数 | D3: うち原価未登録 | E3: 平均原価率 | F3: 平均粗利益
A4: ドリンク | B4: ビール | C4: =COUNTIF(メニュー原価一覧!$C$11:$C$159,B4) -> 9 | D4: =C4-COUNTIFS(メニュー原価一覧!$C$11:$C$159,B4,メニュー原価一覧!$G$11:$G$159,">0") -> 0 | E4: =IFERROR(AVERAGEIFS(メニュー原価一覧!$H$11:$H$159,メニュー原価一覧!$C$11:$C$159,B4,メニュー原価一覧!$G$11:$G$159,">0"),"-") -> 0.3817268 | F4: =IFERROR(AVERAGEIFS(メニュー原価一覧!$I$11:$I$159,メニュー原価一覧!$C$11:$C$159,B4,メニュー原価一覧!$G$11:$G$159,">0"),"-") -> 492
A5: ドリンク | B5: ハイボール | C5: =COUNTIF(メニュー原価一覧!$C$11:$C$159,B5) -> 5 | D5: =C5-COUNTIFS(メニュー原価一覧!$C$11:$C$159,B5,メニュー原価一覧!$G$11:$G$159,">0") -> 0 | E5: =IFERROR(AVERAGEIFS(メニュー原価一覧!$H$11:$H$159,メニュー原価一覧!$C$11:$C$159,B5,メニュー原価一覧!$G$11:$G$159,">0"),"-") -> 0.21320588 | F5: =IFERROR(AVERAGEIFS(メニュー原価一覧!$I$11:$I$159,メニュー原価一覧!$C$11:$C$159,B5,メニュー原価一覧!$G$11:$G$159,">0"),"-") -> 535.02
A6: ドリンク | B6: サワー | C6: =COUNTIF(メニュー原価一覧!$C$11:$C$159,B6) -> 9 | D6: =C6-COUNTIFS(メニュー原価一覧!$C$11:$C$159,B6,メニュー原価一覧!$G$11:$G$159,">0") -> 0 | E6: =IFERROR(AVERAGEIFS(メニュー原価一覧!$H$11:$H$159,メニュー原価一覧!$C$11:$C$159,B6,メニュー原価一覧!$G$11:$G$159,">0"),"-") -> 0.15328139 | F6: =IFERROR(AVERAGEIFS(メニュー原価一覧!$I$11:$I$159,メニュー原価一覧!$C$11:$C$159,B6,メニュー原価一覧!$G$11:$G$159,">0"),"-") -> 491.09679
A7: ドリンク | B7: カクテル・蒸留酒・焼酎 | C7: =COUNTIF(メニュー原価一覧!$C$11:$C$159,B7) -> 8 | D7: =C7-COUNTIFS(メニュー原価一覧!$C$11:$C$159,B7,メニュー原価一覧!$G$11:$G$159,">0") -> 0 | E7: =IFERROR(AVERAGEIFS(メニュー原価一覧!$H$11:$H$159,メニュー原価一覧!$C$11:$C$159,B7,メニュー原価一覧!$G$11:$G$159,">0"),"-") -> 0.17979726 | F7: =IFERROR(AVERAGEIFS(メニュー原価一覧!$I$11:$I$159,メニュー原価一覧!$C$11:$C$159,B7,メニュー原価一覧!$G$11:$G$159,">0"),"-") -> 475.71759
A8: ドリンク | B8: ワイン・果実酒 | C8: =COUNTIF(メニュー原価一覧!$C$11:$C$159,B8) -> 7 | D8: =C8-COUNTIFS(メニュー原価一覧!$C$11:$C$159,B8,メニュー原価一覧!$G$11:$G$159,">0") -> 0 | E8: =IFERROR(AVERAGEIFS(メニュー原価一覧!$H$11:$H$159,メニュー原価一覧!$C$11:$C$159,B8,メニュー原価一覧!$G$11:$G$159,">0"),"-") -> 0.32386228 | F8: =IFERROR(AVERAGEIFS(メニュー原価一覧!$I$11:$I$159,メニュー原価一覧!$C$11:$C$159,B8,メニュー原価一覧!$G$11:$G$159,">0"),"-") -> 651.78571
A9: ドリンク | B9: セット | C9: =COUNTIF(メニュー原価一覧!$C$11:$C$159,B9) -> 2 | D9: =C9-COUNTIFS(メニュー原価一覧!$C$11:$C$159,B9,メニュー原価一覧!$G$11:$G$159,">0") -> 2 | E9: =IFERROR(AVERAGEIFS(メニュー原価一覧!$H$11:$H$159,メニュー原価一覧!$C$11:$C$159,B9,メニュー原価一覧!$G$11:$G$159,">0"),"-") -> - | F9: =IFERROR(AVERAGEIFS(メニュー原価一覧!$I$11:$I$159,メニュー原価一覧!$C$11:$C$159,B9,メニュー原価一覧!$G$11:$G$159,">0"),"-") -> -
A10: フード | B10: 冷製おつまみ | C10: =COUNTIF(メニュー原価一覧!$C$11:$C$159,B10) -> 13 | D10: =C10-COUNTIFS(メニュー原価一覧!$C$11:$C$159,B10,メニュー原価一覧!$G$11:$G$159,">0") -> 1 | E10: =IFERROR(AVERAGEIFS(メニュー原価一覧!$H$11:$H$159,メニュー原価一覧!$C$11:$C$159,B10,メニュー原価一覧!$G$11:$G$159,">0"),"-") -> 0.36093877 | F10: =IFERROR(AVERAGEIFS(メニュー原価一覧!$I$11:$I$159,メニュー原価一覧!$C$11:$C$159,B10,メニュー原価一覧!$G$11:$G$159,">0"),"-") -> 355.59167
A11: フード | B11: 温製おつまみ | C11: =COUNTIF(メニュー原価一覧!$C$11:$C$159,B11) -> 13 | D11: =C11-COUNTIFS(メニュー原価一覧!$C$11:$C$159,B11,メニュー原価一覧!$G$11:$G$159,">0") -> 0 | E11: =IFERROR(AVERAGEIFS(メニュー原価一覧!$H$11:$H$159,メニュー原価一覧!$C$11:$C$159,B11,メニュー原価一覧!$G$11:$G$159,">0"),"-") -> 0.33360508 | F11: =IFERROR(AVERAGEIFS(メニュー原価一覧!$I$11:$I$159,メニュー原価一覧!$C$11:$C$159,B11,メニュー原価一覧!$G$11:$G$159,">0"),"-") -> 415.90769
A12: フード | B12: ピザ | C12: =COUNTIF(メニュー原価一覧!$C$11:$C$159,B12) -> 3 | D12: =C12-COUNTIFS(メニュー原価一覧!$C$11:$C$159,B12,メニュー原価一覧!$G$11:$G$159,">0") -> 0 | E12: =IFERROR(AVERAGEIFS(メニュー原価一覧!$H$11:$H$159,メニュー原価一覧!$C$11:$C$159,B12,メニュー原価一覧!$G$11:$G$159,">0"),"-") -> 0.32928654 | F12: =IFERROR(AVERAGEIFS(メニュー原価一覧!$I$11:$I$159,メニュー原価一覧!$C$11:$C$159,B12,メニュー原価一覧!$G$11:$G$159,">0"),"-") -> 1236.3333
A13: フード | B13: トルティーヤ | C13: =COUNTIF(メニュー原価一覧!$C$11:$C$159,B13) -> 5 | D13: =C13-COUNTIFS(メニュー原価一覧!$C$11:$C$159,B13,メニュー原価一覧!$G$11:$G$159,">0") -> 0 | E13: =IFERROR(AVERAGEIFS(メニュー原価一覧!$H$11:$H$159,メニュー原価一覧!$C$11:$C$159,B13,メニュー原価一覧!$G$11:$G$159,">0"),"-") -> 0.34544828 | F13: =IFERROR(AVERAGEIFS(メニュー原価一覧!$I$11:$I$159,メニュー原価一覧!$C$11:$C$159,B13,メニュー原価一覧!$G$11:$G$159,">0"),"-") -> 379.64
A14: フード | B14: ディッシュ | C14: =COUNTIF(メニュー原価一覧!$C$11:$C$159,B14) -> 3 | D14: =C14-COUNTIFS(メニュー原価一覧!$C$11:$C$159,B14,メニュー原価一覧!$G$11:$G$159,">0") -> 0 | E14: =IFERROR(AVERAGEIFS(メニュー原価一覧!$H$11:$H$159,メニュー原価一覧!$C$11:$C$159,B14,メニュー原価一覧!$G$11:$G$159,">0"),"-") -> 0.33548523 | F14: =IFERROR(AVERAGEIFS(メニュー原価一覧!$I$11:$I$159,メニュー原価一覧!$C$11:$C$159,B14,メニュー原価一覧!$G$11:$G$159,">0"),"-") -> 1049.9333
A15: フード | B15: カレー | C15: =COUNTIF(メニュー原価一覧!$C$11:$C$159,B15) -> 5 | D15: =C15-COUNTIFS(メニュー原価一覧!$C$11:$C$159,B15,メニュー原価一覧!$G$11:$G$159,">0") -> 0 | E15: =IFERROR(AVERAGEIFS(メニュー原価一覧!$H$11:$H$159,メニュー原価一覧!$C$11:$C$159,B15,メニュー原価一覧!$G$11:$G$159,">0"),"-") -> 0.31594047 | F15: =IFERROR(AVERAGEIFS(メニュー原価一覧!$I$11:$I$159,メニュー原価一覧!$C$11:$C$159,B15,メニュー原価一覧!$G$11:$G$159,">0"),"-") -> 809.06
... A25: フード | B25: デザート | C25: =COUNTIF(メニュー原価一覧!$C$11:$C$159,B25) -> 12 | D25: =C25-COUNTIFS(メニュー原価一覧!$C$11:$C$159,B25,メニュー原価一覧!$G$11:$G$159,">0") -> 0 | E25: =IFERROR(AVERAGEIFS(メニュー原価一覧!$H$11:$H$159,メニュー原価一覧!$C$11:$C$159,B25,メニュー原価一覧!$G$11:$G$159,">0"),"-") -> 0.21571632 | F25: =IFERROR(AVERAGEIFS(メニュー原価一覧!$I$11:$I$159,メニュー原価一覧!$C$11:$C$159,B25,メニュー原価一覧!$G$11:$G$159,">0"),"-") -> 392.68333
A26: 合計 | C26: =SUM(C4:C25) -> 149 | D26: =SUM(D4:D25) -> 3 | E26: =メニュー原価一覧!C6 -> 0.28549818 | F26: =メニュー原価一覧!C7 -> 516.42248
