Workbook

Sheet 現状と課題
A1: RAKU SPA 1010 神田 飲食部門 現状と課題（値上げ根拠）
A2: 出典：予実管理表 2026年9月（累計＝2026/4〜9月、単位：千円）／期間報 2026/4/1〜6/30（税抜・円）。青字＝資料から転記した数値
A4: ① 飲食売上・原価（2026年4〜9月累計／千円）
A5: 項目 | B5: 予算 | C5: 実績 | D5: 予算比 | E5: 前期実績 | F5: 前期比 | G5: 前期差
A6: 飲食売上 | B6: 61825.8 | C6: 54943.4 | D6: =C6/B6 -> 0.88868078 | E6: 68259.9 | F6: =C6/E6 -> 0.80491474 | G6: =C6-E6 -> -13316.5
A7: うちコラボ | B7: 33007 | C7: 25737.2 | D7: =C7/B7 -> 0.77974975 | E7: 38650.2 | F7: =C7/E7 -> 0.66590082 | G7: =C7-E7 -> -12913
A8: うちコラボ抜き（食事） | B8: 28818.8 | C8: 29206.2 | D8: =C8/B8 -> 1.0134426 | E8: 29609.7 | F8: =C8/E8 -> 0.98637271 | G8: =C8-E8 -> -403.5
A9: 飲食売上原価 | B9: 20648.8 | C9: 20011.7 | D9: =C9/B9 -> 0.96914591 | E9: 22344.5 | F9: =C9/E9 -> 0.89559847 | G9: =C9-E9 -> -2332.8
A10: 飲食粗利益 | B10: 41177 | C10: 34931.8 | D10: =C10/B10 -> 0.84833281 | E10: 45915.4 | F10: =C10/E10 -> 0.76078614 | G10: =C10-E10 -> -10983.6
A11: 飲食原価率 | B11: =B9/B6 -> 0.33398355 | C11: =C9/C6 -> 0.36422391 | D11: =(C11-B11)*100 -> 3.0240363 | E11: =E9/E6 -> 0.32734446 | F11: =(C11-E11)*100 -> 3.6879452 | G11: ←予算比・前期比はポイント差
A12: コラボ構成比 | B12: =B7/B6 -> 0.53387097 | C12: =C7/C6 -> 0.46843115 | D12: =(C12-B12)*100 -> -6.5439824 | E12: =E7/E6 -> 0.56622116 | F12: =(C12-E12)*100 -> -9.7790014
A13: 9月単月 飲食原価率 | B13: =2882.1/8549.2 -> 0.33711926 | C13: =3274.3/8617.7 -> 0.37995057 | D13: =(C13-B13)*100 -> 4.2831304 | E13: =3597.6/10442.7 -> 0.3445086 | F13: =(C13-E13)*100 -> 3.5441963 | G13: 予実管理表 9月単月より
A15: ② 分類別売上（2026年4〜6月／税抜・円）
A16: 分類 | B16: 数量 | C16: 金額 | D16: 前年数量 | E16: 前年金額 | F16: 金額 前年比 | G16: 数量 前年比
A17: アルコール | B17: 3413 | C17: 2064487 | D17: 4415 | E17: 2739753 | F17: =C17/E17 -> 0.75353034 | G17: =IF(D17>0,B17/D17,"-") -> 0.77304643
A18: ソフトドリンク | B18: 4017 | C18: 1501751 | D18: 3769 | E18: 1424375 | F18: =C18/E18 -> 1.0543228 | G18: =IF(D18>0,B18/D18,"-") -> 1.0657999
A19: 麺類 | B19: 2336 | C19: 2498119 | D19: 2414 | E19: 2324661 | F19: =C19/E19 -> 1.0746165 | G19: =IF(D19>0,B19/D19,"-") -> 0.96768848
A20: ご飯類 | B20: 4213 | C20: 4640988 | D20: 3552 | E20: 3605428 | F20: =C20/E20 -> 1.2872225 | G20: =IF(D20>0,B20/D20,"-") -> 1.1860923
A21: 一品料理 | B21: 3125 | C21: 2319191 | D21: 3971 | E21: 2760249 | F21: =C21/E21 -> 0.84021079 | G21: =IF(D21>0,B21/D21,"-") -> 0.78695543
A22: デザート類 | B22: 1251 | C22: 607609 | D22: 1307 | E22: 644282 | F22: =C22/E22 -> 0.94307927 | G22: =IF(D22>0,B22/D22,"-") -> 0.95715379
A23: ランチ | B23: 9 | C23: 6507 | D23: 133 | E23: 116063 | F23: =C23/E23 -> 0.056064379 | G23: =IF(D23>0,B23/D23,"-") -> 0.067669173
A24: その他飲食 | B24: 34717 | C24: 31561 | D24: -277 | E24: 36448 | F24: =C24/E24 -> 0.86591857 | G24: =IF(D24>0,B24/D24,"-") -> -
A25: セレクト | B25: 1590 | C25: 432229 | D25: 1656 | E25: 83138 | F25: =C25/E25 -> 5.1989343 | G25: =IF(D25>0,B25/D25,"-") -> 0.96014493
A26: 飲食（コラボ） | B26: 10983 | C26: 14608931 | D26: 18021 | E26: 23070708 | F26: =C26/E26 -> 0.63322422 | G26: =IF(D26>0,B26/D26,"-") -> 0.60945564
A27: コラボ抜き 小計 | C27: =SUM(C17:C25) -> 14102442 | E27: =SUM(E17:E25) -> 13734397 | F27: =C27/E27 -> 1.0267973
A28: 飲食 合計 | C28: =SUM(C17:C26) -> 28711373 | E28: =SUM(E17:E26) -> 36805105 | F28: =C28/E28 -> 0.78009214
A30: ③ 客数・客単価（2026年4〜6月）
A31: 項目 | B31: 実績 | C31: 前年同日 | D31: 前年比
A32: 飲食者数（人） | B32: 16008 | C32: 18556 | D32: =B32/C32 -> 0.86268592
A33: 飲食客単価（円） | B33: 1776 | C33: 1974 | D33: =B33/C33 -> 0.89969605
A34: 入館者数（人） | B34: 74639 | C34: 77738 | D34: =B34/C34 -> 0.96013533
A35: アルコール注文率（杯／飲食者） | B35: =B17/B32 -> 0.2132059 | C35: =D17/C32 -> 0.23792843 | D35: =B35/C35 -> 0.89609255
A36: アルコール平均単価（円） | B36: =C17/B17 -> 604.88925 | C36: =E17/D17 -> 620.55561 | D36: =B36/C36 -> 0.9747543

Sheet 分類別値上げ率
A1: 分類別 実効値上げ率（実際の販売数で加重）
A2: 品目別値上げ効果シートを分類ごとに集計。実効値上げ率＝値上げ額÷改定前の定価ベース売上
A4: 分類 | B4: 4〜6月売上（税抜・円） | C4: 値上げ額（3か月） | D4: 実効値上げ率 | E4: 理論原価率 改定前 | F4: 理論原価率 改定後 | G4: 年間換算 値上げ額
A5: アルコール | B5: =SUMIF(品目別値上げ効果!$C$5:$C$216,"アルコール",品目別値上げ効果!$E$5:$E$216) -> 1897327 | C5: =SUMIF(品目別値上げ効果!$C$5:$C$216,"アルコール",品目別値上げ効果!$I$5:$I$216) -> 47951 | D5: =IFERROR(C5/SUMIF(品目別値上げ効果!$C$5:$C$216,"アルコール",品目別値上げ効果!$J$5:$J$216),0) -> 0.024583474 | E5: =IFERROR(SUMIF(品目別値上げ効果!$C$5:$C$216,"アルコール",品目別値上げ効果!$L$5:$L$216)/SUMIF(品目別値上げ効果!$C$5:$C$216,"アルコール",品目別値上げ効果!$M$5:$M$216),"-") -> 0.33067645 | F5: =IFERROR(SUMIF(品目別値上げ効果!$C$5:$C$216,"アルコール",品目別値上げ効果!$L$5:$L$216)/(SUMIF(品目別値上げ効果!$C$5:$C$216,"アルコール",品目別値上げ効果!$M$5:$M$216)+SUMIF(品目別値上げ効果!$C$5:$C$216,"アルコール",品目別値上げ効果!$N$5:$N$216)),"-") -> 0.32135175 | G5: =C5*4 -> 191804
A6: ソフトドリンク | B6: =SUMIF(品目別値上げ効果!$C$5:$C$216,"ソフトドリンク",品目別値上げ効果!$E$5:$E$216) -> 1388847 | C6: =SUMIF(品目別値上げ効果!$C$5:$C$216,"ソフトドリンク",品目別値上げ効果!$I$5:$I$216) -> 42606 | D6: =IFERROR(C6/SUMIF(品目別値上げ効果!$C$5:$C$216,"ソフトドリンク",品目別値上げ効果!$J$5:$J$216),0) -> 0.028516927 | E6: =IFERROR(SUMIF(品目別値上げ効果!$C$5:$C$216,"ソフトドリンク",品目別値上げ効果!$L$5:$L$216)/SUMIF(品目別値上げ効果!$C$5:$C$216,"ソフトドリンク",品目別値上げ効果!$M$5:$M$216),"-") -> 0.21774765 | F6: =IFERROR(SUMIF(品目別値上げ効果!$C$5:$C$216,"ソフトドリンク",品目別値上げ効果!$L$5:$L$216)/(SUMIF(品目別値上げ効果!$C$5:$C$216,"ソフトドリンク",品目別値上げ効果!$M$5:$M$216)+SUMIF(品目別値上げ効果!$C$5:$C$216,"ソフトドリンク",品目別値上げ効果!$N$5:$N$216)),"-") -> 0.21171033 | G6: =C6*4 -> 170424
A7: 麺類 | B7: =SUMIF(品目別値上げ効果!$C$5:$C$216,"麺類",品目別値上げ効果!$E$5:$E$216) -> 1743018 | C7: =SUMIF(品目別値上げ効果!$C$5:$C$216,"麺類",品目別値上げ効果!$I$5:$I$216) -> 72112 | D7: =IFERROR(C7/SUMIF(品目別値上げ効果!$C$5:$C$216,"麺類",品目別値上げ効果!$J$5:$J$216),0) -> 0.041243623 | E7: =IFERROR(SUMIF(品目別値上げ効果!$C$5:$C$216,"麺類",品目別値上げ効果!$L$5:$L$216)/SUMIF(品目別値上げ効果!$C$5:$C$216,"麺類",品目別値上げ効果!$M$5:$M$216),"-") -> 0.29677192 | F7: =IFERROR(SUMIF(品目別値上げ効果!$C$5:$C$216,"麺類",品目別値上げ効果!$L$5:$L$216)/(SUMIF(品目別値上げ効果!$C$5:$C$216,"麺類",品目別値上げ効果!$M$5:$M$216)+SUMIF(品目別値上げ効果!$C$5:$C$216,"麺類",品目別値上げ効果!$N$5:$N$216)),"-") -> 0.2850168 | G7: =C7*4 -> 288448
A8: ご飯類 | B8: =SUMIF(品目別値上げ効果!$C$5:$C$216,"ご飯類",品目別値上げ効果!$E$5:$E$216) -> 3402183 | C8: =SUMIF(品目別値上げ効果!$C$5:$C$216,"ご飯類",品目別値上げ効果!$I$5:$I$216) -> 97686 | D8: =IFERROR(C8/SUMIF(品目別値上げ効果!$C$5:$C$216,"ご飯類",品目別値上げ効果!$J$5:$J$216),0) -> 0.028547799 | E8: =IFERROR(SUMIF(品目別値上げ効果!$C$5:$C$216,"ご飯類",品目別値上げ効果!$L$5:$L$216)/SUMIF(品目別値上げ効果!$C$5:$C$216,"ご飯類",品目別値上げ効果!$M$5:$M$216),"-") -> 0.34141046 | F8: =IFERROR(SUMIF(品目別値上げ効果!$C$5:$C$216,"ご飯類",品目別値上げ効果!$L$5:$L$216)/(SUMIF(品目別値上げ効果!$C$5:$C$216,"ご飯類",品目別値上げ効果!$M$5:$M$216)+SUMIF(品目別値上げ効果!$C$5:$C$216,"ご飯類",品目別値上げ効果!$N$5:$N$216)),"-") -> 0.33193446 | G8: =C8*4 -> 390744
A9: 一品料理 | B9: =SUMIF(品目別値上げ効果!$C$5:$C$216,"一品料理",品目別値上げ効果!$E$5:$E$216) -> 2198332 | C9: =SUMIF(品目別値上げ効果!$C$5:$C$216,"一品料理",品目別値上げ効果!$I$5:$I$216) -> 96471 | D9: =IFERROR(C9/SUMIF(品目別値上げ効果!$C$5:$C$216,"一品料理",品目別値上げ効果!$J$5:$J$216),0) -> 0.043899542 | E9: =IFERROR(SUMIF(品目別値上げ効果!$C$5:$C$216,"一品料理",品目別値上げ効果!$L$5:$L$216)/SUMIF(品目別値上げ効果!$C$5:$C$216,"一品料理",品目別値上げ効果!$M$5:$M$216),"-") -> 0.33632017 | F9: =IFERROR(SUMIF(品目別値上げ効果!$C$5:$C$216,"一品料理",品目別値上げ効果!$L$5:$L$216)/(SUMIF(品目別値上げ効果!$C$5:$C$216,"一品料理",品目別値上げ効果!$M$5:$M$216)+SUMIF(品目別値上げ効果!$C$5:$C$216,"一品料理",品目別値上げ効果!$N$5:$N$216)),"-") -> 0.32220731 | G9: =C9*4 -> 385884
A10: デザート類 | B10: =SUMIF(品目別値上げ効果!$C$5:$C$216,"デザート類",品目別値上げ効果!$E$5:$E$216) -> 587332 | C10: =SUMIF(品目別値上げ効果!$C$5:$C$216,"デザート類",品目別値上げ効果!$I$5:$I$216) -> 31293 | D10: =IFERROR(C10/SUMIF(品目別値上げ効果!$C$5:$C$216,"デザート類",品目別値上げ効果!$J$5:$J$216),0) -> 0.053280098 | E10: =IFERROR(SUMIF(品目別値上げ効果!$C$5:$C$216,"デザート類",品目別値上げ効果!$L$5:$L$216)/SUMIF(品目別値上げ効果!$C$5:$C$216,"デザート類",品目別値上げ効果!$M$5:$M$216),"-") -> 0.23636218 | F10: =IFERROR(SUMIF(品目別値上げ効果!$C$5:$C$216,"デザート類",品目別値上げ効果!$L$5:$L$216)/(SUMIF(品目別値上げ効果!$C$5:$C$216,"デザート類",品目別値上げ効果!$M$5:$M$216)+SUMIF(品目別値上げ効果!$C$5:$C$216,"デザート類",品目別値上げ効果!$N$5:$N$216)),"-") -> 0.22440582 | G10: =C10*4 -> 125172
A11: 価格表にない商品（据え置き） | B11: =SUMIF(品目別値上げ効果!$C$5:$C$216,"対象外",品目別値上げ効果!$E$5:$E$216) -> 2885403 | C11: =SUMIF(品目別値上げ効果!$C$5:$C$216,"対象外",品目別値上げ効果!$I$5:$I$216) -> 0 | D11: =IFERROR(C11/SUMIF(品目別値上げ効果!$C$5:$C$216,"対象外",品目別値上げ効果!$J$5:$J$216),0) -> 0 | E11: =IFERROR(SUMIF(品目別値上げ効果!$C$5:$C$216,"対象外",品目別値上げ効果!$L$5:$L$216)/SUMIF(品目別値上げ効果!$C$5:$C$216,"対象外",品目別値上げ効果!$M$5:$M$216),"-") -> - | F11: =IFERROR(SUMIF(品目別値上げ効果!$C$5:$C$216,"対象外",品目別値上げ効果!$L$5:$L$216)/(SUMIF(品目別値上げ効果!$C$5:$C$216,"対象外",品目別値上げ効果!$M$5:$M$216)+SUMIF(品目別値上げ効果!$C$5:$C$216,"対象外",品目別値上げ効果!$N$5:$N$216)),"-") -> - | G11: =C11*4 -> 0
A12: コラボ抜き 合計 | B12: =現状と課題!C27 -> 14102442 | C12: =SUM(C5:C11) -> 388119 | D12: =C12/B12 -> 0.027521404 | E12: =SUM(品目別値上げ効果!$L$5:$L$216)/SUM(品目別値上げ効果!$M$5:$M$216) -> 0.30955564 | F12: =SUM(品目別値上げ効果!$L$5:$L$216)/(SUM(品目別値上げ効果!$M$5:$M$216)+SUM(品目別値上げ効果!$N$5:$N$216)) -> 0.29910656 | G12: =C12*4 -> 1552476
A13: ※ 合計の実効値上げ率は、据え置き商品・価格表にない商品も含めたコラボ抜き売上全体に対する率です。
A15: 追加値上げ候補（価格表にない売れ筋・据え置きの売れ筋）
A16: 商品 | B16: 4〜6月数量 | C16: 現在の税抜単価 | D16: 値上げ額（税抜）✎ | E16: 値上げ後 税込 | F16: 3か月の増収 | G16: 年間換算
A17: 近江牛サウナカリー | B17: 964 | C17: 1232 | D17: 45 | E17: =ROUND((C17+D17)*1.1,0) -> 1405 | F17: =B17*D17 -> 43380 | G17: =F17*4 -> 173520
A18: リポスパ | B18: 2134 | C18: 430 | D18: 18 | E18: =ROUND((C18+D18)*1.1,0) -> 493 | F18: =B18*D18 -> 38412 | G18: =F18*4 -> 153648
A19: コインメックビール | B19: 605 | C19: 454 | D19: 0 | E19: =ROUND((C19+D19)*1.1,0) -> 499 | F19: =B19*D19 -> 0 | G19: =F19*4 -> 0
A20: 1010ハイボールセット | B20: 84 | C20: 1006 | D20: 0 | E20: =ROUND((C20+D20)*1.1,0) -> 1107 | F20: =B20*D20 -> 0 | G20: =F20*4 -> 0
A21: 追加候補 合計 | F21: =SUM(F17:F20) -> 81792 | G21: =SUM(G17:G20) -> 327168
A22: ※ 現在の税抜単価は4〜6月の売上÷数量。値上げ額（黄色）は仮の数字です。0のままなら据え置き。

Sheet 売上想定
A1: 値上げ後の売上・粗利想定（コラボ抜き）
A2: 黄色セル＝前提条件（変更すると全体が再計算されます）
A4: 前提条件
A5: コラボ抜き売上 4〜9月実績（千円） | B5: =現状と課題!C8 -> 29206.2 | C5: 予実管理表 9月 累計「食事」
A6: 年間換算ベース売上（千円） | B6: =B5*2 -> 58412.4 | C6: 上期×2で年換算
A7: 追加候補を含める（1＝含める／0＝含めない） | B7: 0 | C7: 分類別値上げ率シートの「追加値上げ候補」
A8: 実効値上げ率（税抜・販売数で加重） | B8: =(分類別値上げ率!C12+B7*分類別値上げ率!F21)/分類別値上げ率!B12 -> 0.027521404 | C8: 値上げ額÷コラボ抜き売上（4〜6月の品目別実績）
A9: 原価率（実績） | B9: =現状と課題!C11 -> 0.36422391 | C9: 4〜9月の飲食原価率。値上げ後も1品あたり原価は不変と仮定
A11: 粗利が値上げ前と同じになる数量減（損益分岐） | B11: =1-(1-B9)/(1+B8-B9) -> 0.041491795 | C11: この割合まで販売数が減っても粗利額は減らない
A12: 売上が値上げ前と同じになる数量減 | B12: =B8/(1+B8) -> 0.026784263
A14: シナリオ別 年間想定（千円）
A15: シナリオ | B15: 販売数の変化 | C15: 年間売上（値上げ後） | D15: 売上増減 | E15: 年間粗利（値上げ後） | F15: 粗利増減 | G15: 半期（6か月）売上増減 | H15: 半期 粗利増減
A16: 値上げ前（ベース） | B16: 0 | C16: =B6 -> 58412.4 | E16: =B6*(1-B9) -> 37137.207
A17: 客離れなし | B17: 0 | C17: =$B$6*(1+$B$8)*(1+B17) -> 60019.991 | D17: =C17-$C$16 -> 1607.5912 | E17: =$B$6*(1+B17)*(1+$B$8-$B$9) -> 38744.798 | F17: =E17-$E$16 -> 1607.5912 | G17: =D17/2 -> 803.79562 | H17: =F17/2 -> 803.79562
A18: やや減少 | B18: -0.01 | C18: =$B$6*(1+$B$8)*(1+B18) -> 59419.791 | D18: =C18-$C$16 -> 1007.3913 | E18: =$B$6*(1+B18)*(1+$B$8-$B$9) -> 38357.351 | F18: =E18-$E$16 -> 1220.1433 | G18: =D18/2 -> 503.69567 | H18: =F18/2 -> 610.07163
A19: 想定（標準） | B19: -0.02 | C19: =$B$6*(1+$B$8)*(1+B19) -> 58819.591 | D19: =C19-$C$16 -> 407.19142 | E19: =$B$6*(1+B19)*(1+$B$8-$B$9) -> 37969.903 | F19: =E19-$E$16 -> 832.69527 | G19: =D19/2 -> 203.59571 | H19: =F19/2 -> 416.34764
A20: 慎重 | B20: -0.03 | C20: =$B$6*(1+$B$8)*(1+B20) -> 58219.392 | D20: =C20-$C$16 -> -193.00849 | E20: =$B$6*(1+B20)*(1+$B$8-$B$9) -> 37582.455 | F20: =E20-$E$16 -> 445.24729 | G20: =D20/2 -> -96.504247 | H20: =F20/2 -> 222.62364
A22: 値上げ後の飲食原価率（想定） | B22: =B9/(1+B8) -> 0.35446844 | C22: 同じ原価で売価だけ上がった場合の原価率
A24: ※ コラボ売上は値上げ対象外のため含めていません。
A25: ※ 販売数の変化は仮定です。値上げ後1〜2か月の実績で見直してください。

Sheet 品目別値上げ効果
A1: 品目別 値上げ効果（2026年4〜6月の販売数で試算）
A2: 出典：期間報（商品別）2026/4/1〜6/30 税抜／メニュー原価一覧（最新版）。販売数×税抜差額＝値上げで増える売上（販売数が変わらない場合）
A4: POS商品名 | B4: メニュー名 | C4: 分類 | D4: 数量 | E4: 売上（税抜） | F4: 改定前 税抜 | G4: 改定後 税抜 | H4: 差額 | I4: 値上げ額 | J4: 定価ベース売上 | K4: 原価単価 | L4: 原価計 | M4: 原価登録分 定価売上 | N4: 原価登録分 値上げ額
A5: 2025)パイントグラス | B5: アサヒスーパードライ（パイントグラス） | C5: アルコール | D5: 416 | E5: 323271 | F5: 777 | G5: 777 | H5: =G5-F5 -> 0 | I5: =D5*H5 -> 0 | J5: =D5*F5 -> 323232 | K5: 284.4 | L5: =D5*K5 -> 118310.4 | M5: =IF(K5>0,J5,0) -> 323232 | N5: =IF(K5>0,I5,0) -> 0
A6: 2025)1010セット | B6: 1010セット（タパス付） | C6: アルコール | D6: 279 | E6: 279672 | F6: 1010 | G6: 1010 | H6: =G6-F6 -> 0 | I6: =D6*H6 -> 0 | J6: =D6*F6 -> 281790 | L6: =D6*K6 -> 0 | M6: =IF(K6>0,J6,0) -> 0 | N6: =IF(K6>0,I6,0) -> 0
A7: 2025)マルエフ | B7: マルエフ | C7: アルコール | D7: 327 | E7: 254117 | F7: 777 | G7: 777 | H7: =G7-F7 -> 0 | I7: =D7*H7 -> 0 | J7: =D7*F7 -> 254079 | K7: 307.2 | L7: =D7*K7 -> 100454.4 | M7: =IF(K7>0,J7,0) -> 254079 | N7: =IF(K7>0,I7,0) -> 0
A8: 2025)熟選ビール | B8: 熟撰 | C8: アルコール | D8: 281 | E8: 218364 | F8: 777 | G8: 777 | H8: =G8-F8 -> 0 | I8: =D8*H8 -> 0 | J8: =D8*F8 -> 218337 | K8: 321.7 | L8: =D8*K8 -> 90397.7 | M8: =IF(K8>0,J8,0) -> 218337 | N8: =IF(K8>0,I8,0) -> 0
A9: 2025)黒生 | B9: 黒生 | C9: アルコール | D9: 180 | E9: 139871 | F9: 777 | G9: 777 | H9: =G9-F9 -> 0 | I9: =D9*H9 -> 0 | J9: =D9*F9 -> 139860 | K9: 307.2 | L9: =D9*K9 -> 55296 | M9: =IF(K9>0,J9,0) -> 139860 | N9: =IF(K9>0,I9,0) -> 0
A10: 2025)JUGビール | B10: 1010JUGビール（800ml） | C10: アルコール | D10: 80 | E10: 74400 | F10: 930 | G10: 1203 | H10: =G10-F10 -> 273 | I10: =D10*H10 -> 21840 | J10: =D10*F10 -> 74400 | K10: 568.8 | L10: =D10*K10 -> 45504 | M10: =IF(K10>0,J10,0) -> 74400 | N10: =IF(K10>0,I10,0) -> 21840
A11: 2025)ハイボールレギュラー | B11: ハイボール | C11: アルコール | D11: 128 | E11: 71760 | F11: 680 | G11: 698 | H11: =G11-F11 -> 18 | I11: =D11*H11 -> 2304 | J11: =D11*F11 -> 87040 | K11: 53.5 | L11: =D11*K11 -> 6848 | M11: =IF(K11>0,J11,0) -> 87040 | N11: =IF(K11>0,I11,0) -> 2304
A12: 2025)匠の深絞りレモンサワー | B12: 匠の深絞りレモンサワー | C12: アルコール | D12: 97 | E12: 48922 | F12: 580 | G12: 607 | H12: =G12-F12 -> 27 | I12: =D12*H12 -> 2619 | J12: =D12*F12 -> 56260 | K12: 76.42885 | L12: =D12*K12 -> 7413.5984 | M12: =IF(K12>0,J12,0) -> 56260 | N12: =IF(K12>0,I12,0) -> 2619
A13: 2025)ピルスナーウルケル | B13: ピルスナー・ウルケル | C13: アルコール | D13: 44 | E13: 38720 | F13: 880 | G13: 898 | H13: =G13-F13 -> 18 | I13: =D13*H13 -> 792 | J13: =D13*F13 -> 38720 | K13: 296 | L13: =D13*K13 -> 13024 | M13: =IF(K13>0,J13,0) -> 38720 | N13: =IF(K13>0,I13,0) -> 792
A14: 2025)塩レモンサワー | B14: 塩レモンサワー | C14: アルコール | D14: 65 | E14: 34700 | F14: 580 | G14: 607 | H14: =G14-F14 -> 27 | I14: =D14*H14 -> 1755 | J14: =D14*F14 -> 37700 | K14: 81.8 | L14: =D14*K14 -> 5317 | M14: =IF(K14>0,J14,0) -> 37700 | N14: =IF(K14>0,I14,0) -> 1755
A15: 2025)ペローニ | B15: ペローニ | C15: アルコール | D15: 39 | E15: 34322 | F15: 880 | G15: 898 | H15: =G15-F15 -> 18 | I15: =D15*H15 -> 702 | J15: =D15*F15 -> 34320 | K15: 310 | L15: =D15*K15 -> 12090 | M15: =IF(K15>0,J15,0) -> 34320 | N15: =IF(K15>0,I15,0) -> 702
A16: 2025)シチリアレモンサワー | B16: シチリアレモンサワー | C16: アルコール | D16: 72 | E16: 33840 | F16: 580 | G16: 607 | H16: =G16-F16 -> 27 | I16: =D16*H16 -> 1944 | J16: =D16*F16 -> 41760 | K16: 80.4 | L16: =D16*K16 -> 5788.8 | M16: =IF(K16>0,J16,0) -> 41760 | N16: =IF(K16>0,I16,0) -> 1944
A17: 2025)塩ライチサワー | B17: 塩ライチサワー | C17: アルコール | D17: 54 | E17: 31320 | F17: 580 | G17: 607 | H17: =G17-F17 -> 27 | I17: =D17*H17 -> 1458 | J17: =D17*F17 -> 31320 | K17: 81.8 | L17: =D17*K17 -> 4417.2 | M17: =IF(K17>0,J17,0) -> 31320 | N17: =IF(K17>0,I17,0) -> 1458
A18: 2025)マンゴーサワー | B18: マンゴーサワー | C18: アルコール | D18: 48 | E18: 27840 | F18: 580 | G18: 607 | H18: =G18-F18 -> 27 | I18: =D18*H18 -> 1296 | J18: =D18*F18 -> 27840 | K18: 133.6 | L18: =D18*K18 -> 6412.8 | M18: =IF(K18>0,J18,0) -> 27840 | N18: =IF(K18>0,I18,0) -> 1296
... A25: 2025)カシスオレンジ | B25: カシスオレンジ | C25: アルコール | D25: 26 | E25: 15080 | F25: 580 | G25: 607 | H25: =G25-F25 -> 27 | I25: =D25*H25 -> 702 | J25: =D25*F25 -> 15080 | K25: 243.6 | L25: =D25*K25 -> 6333.6 | M25: =IF(K25>0,J25,0) -> 15080 | N25: =IF(K25>0,I25,0) -> 702
A26: 2025)セットタパス308円 | B26: タパスセット | C26: アルコール | D26: 58 | E26: 14980 | F26: 280 | G26: 280 | H26: =G26-F26 -> 0 | I26: =D26*H26 -> 0 | J26: =D26*F26 -> 16240 | L26: =D26*K26 -> 0 | M26: =IF(K26>0,J26,0) -> 0 | N26: =IF(K26>0,I26,0) -> 0
A27: 2025)モスコミュール | B27: モスコミュール | C27: アルコール | D27: 25 | E27: 14500 | F27: 580 | G27: 607 | H27: =G27-F27 -> 27 | I27: =D27*H27 -> 675 | J27: =D27*F27 -> 14500 | K27: 116.2 | L27: =D27*K27 -> 2905 | M27: =IF(K27>0,J27,0) -> 14500 | N27: =IF(K27>0,I27,0) -> 675
A28: ニッカ 弘前 生シードル ロゼ | B28: ニッカ 弘前 生シードル ロゼ（200ml） | C28: アルコール | D28: 21 | E28: 14280 | F28: 680 | G28: 707 | H28: =G28-F28 -> 27 | I28: =D28*H28 -> 567 | J28: =D28*F28 -> 14280 | K28: 270 | L28: =D28*K28 -> 5670 | M28: =IF(K28>0,J28,0) -> 14280 | N28: =IF(K28>0,I28,0) -> 567
A29: 2025)ジンジャーハイレギュラー | B29: ジンジャーハイ | C29: アルコール | D29: 17 | E29: 11560 | F29: 680 | G29: 698 | H29: =G29-F29 -> 18 | I29: =D29*H29 -> 306 | J29: =D29*F29 -> 11560 | K29: 226.2 | L29: =D29*K29 -> 3845.4 | M29: =IF(K29>0,J29,0) -> 11560 | N29: =IF(K29>0,I29,0) -> 306
A30: 2025)ガリゲットルージュ ボトル | B30: ガリゲット・バリグール 赤（ボトル750ml） | C30: アルコール | D30: 6 | E30: 10680 | F30: 1780 | G30: 1816 | H30: =G30-F30 -> 36 | I30: =D30*H30 -> 216 | J30: =D30*F30 -> 10680 | K30: 680 | L30: =D30*K30 -> 4080 | M30: =IF(K30>0,J30,0) -> 10680 | N30: =IF(K30>0,I30,0) -> 216
A31: 2025)カルピスサワー | B31: カルピスサワー | C31: アルコール | D31: 18 | E31: 10440 | F31: 580 | G31: 607 | H31: =G31-F31 -> 27 | I31: =D31*H31 -> 486 | J31: =D31*F31 -> 10440 | K31: 89.3 | L31: =D31*K31 -> 1607.4 | M31: =IF(K31>0,J31,0) -> 10440 | N31: =IF(K31>0,I31,0) -> 486
A32: 2025)コークハイレギュラー | B32: コークハイ | C32: アルコール | D32: 15 | E32: 10200 | F32: 680 | G32: 698 | H32: =G32-F32 -> 18 | I32: =D32*H32 -> 270 | J32: =D32*F32 -> 10200 | K32: 172 | L32: =D32*K32 -> 2580 | M32: =IF(K32>0,J32,0) -> 10200 | N32: =IF(K32>0,I32,0) -> 270
A33: 新芳醇梅酒 | B33: 芳醇梅酒 | C33: アルコール | D33: 23 | E33: 10028 | F33: 530 | G33: 557 | H33: =G33-F33 -> 27 | I33: =D33*H33 -> 621 | J33: =D33*F33 -> 12190 | K33: 64.3 | L33: =D33*K33 -> 1478.9 | M33: =IF(K33>0,J33,0) -> 12190 | N33: =IF(K33>0,I33,0) -> 621
A34: 2025)マテウスロゼ | B34: マテウス ロゼ（187ml） | C34: アルコール | D34: 7 | E34: 8260 | F34: 1180 | G34: 1207 | H34: =G34-F34 -> 27 | I34: =D34*H34 -> 189 | J34: =D34*F34 -> 8260 | K34: 420 | L34: =D34*K34 -> 2940 | M34: =IF(K34>0,J34,0) -> 8260 | N34: =IF(K34>0,I34,0) -> 189
A35: 2025)塩オレンジサワー | B35: 塩オレンジサワー | C35: アルコール | D35: 13 | E35: 7540 | F35: 580 | G35: 607 | H35: =G35-F35 -> 27 | I35: =D35*H35 -> 351 | J35: =D35*F35 -> 7540 | K35: 80.4 | L35: =D35*K35 -> 1045.2 | M35: =IF(K35>0,J35,0) -> 7540 | N35: =IF(K35>0,I35,0) -> 351
A36: 新麦焼酎 | B36: 麦焼酎 | C36: アルコール | D36: 17 | E36: 7413 | F36: 580 | G36: 607 | H36: =G36-F36 -> 27 | I36: =D36*H36 -> 459 | J36: =D36*F36 -> 9860 | K36: 78.8 | L36: =D36*K36 -> 1339.6 | M36: =IF(K36>0,J36,0) -> 9860 | N36: =IF(K36>0,I36,0) -> 459
A37: 2025)ガリゲットブラン ボトル | B37: ガリゲット・バリグール 白（ボトル750ml） | C37: アルコール | D37: 4 | E37: 7120 | F37: 1780 | G37: 1816 | H37: =G37-F37 -> 36 | I37: =D37*H37 -> 144 | J37: =D37*F37 -> 7120 | K37: 680 | L37: =D37*K37 -> 2720 | M37: =IF(K37>0,J37,0) -> 7120 | N37: =IF(K37>0,I37,0) -> 144
A38: 2025)ウーロンハイ | B38: ウーロンハイ | C38: アルコール | D38: 11 | E38: 6380 | F38: 580 | G38: 607 | H38: =G38-F38 -> 27 | I38: =D38*H38 -> 297 | J38: =D38*F38 -> 6380 | K38: 55.3 | L38: =D38*K38 -> 608.3 | M38: =IF(K38>0,J38,0) -> 6380 | N38: =IF(K38>0,I38,0) -> 297
... A137: 生ハム | B137: 生ハム | C137: 一品料理 | D137: 21 | E137: 7980 | F137: 380 | G137: 407 | H137: =G137-F137 -> 27 | I137: =D137*H137 -> 567 | J137: =D137*F137 -> 7980 | K137: 111.6 | L137: =D137*K137 -> 2343.6 | M137: =IF(K137>0,J137,0) -> 7980 | N137: =IF(K137>0,I137,0) -> 567
A138: タパス | B138: タパス | C138: 一品料理 | D138: 21 | E138: 7980 | F138: 380 | G138: 407 | H138: =G138-F138 -> 27 | I138: =D138*H138 -> 567 | J138: =D138*F138 -> 7980 | L138: =D138*K138 -> 0 | M138: =IF(K138>0,J138,0) -> 0 | N138: =IF(K138>0,I138,0) -> 0
A139: ガーリック枝豆 | B139: ガーリック枝豆 | C139: 一品料理 | D139: 11 | E139: 5280 | F139: 480 | G139: 507 | H139: =G139-F139 -> 27 | I139: =D139*H139 -> 297 | J139: =D139*F139 -> 5280 | K139: 93.9 | L139: =D139*K139 -> 1032.9 | M139: =IF(K139>0,J139,0) -> 5280 | N139: =IF(K139>0,I139,0) -> 297
A140: 2025)トルティーヤエビフライ | B140: トルティーヤ エビフライ | C140: 一品料理 | D140: 8 | E140: 4968 | F140: 580 | G140: 625 | H140: =G140-F140 -> 45 | I140: =D140*H140 -> 360 | J140: =D140*F140 -> 4640 | K140: 230.6 | L140: =D140*K140 -> 1844.8 | M140: =IF(K140>0,J140,0) -> 4640 | N140: =IF(K140>0,I140,0) -> 360
A141: 2025)シュリンプカクテル | B141: シュリンプカクテル | C141: 一品料理 | D141: 4 | E141: 3120 | F141: 780 | G141: 807 | H141: =G141-F141 -> 27 | I141: =D141*H141 -> 108 | J141: =D141*F141 -> 3120 | K141: 192.2 | L141: =D141*K141 -> 768.8 | M141: =IF(K141>0,J141,0) -> 3120 | N141: =IF(K141>0,I141,0) -> 108
A142: カマンベールチーズ | B142: カマンベールチーズ | C142: 一品料理 | D142: 6 | E142: 2280 | F142: 380 | G142: 407 | H142: =G142-F142 -> 27 | I142: =D142*H142 -> 162 | J142: =D142*F142 -> 2280 | K142: 211 | L142: =D142*K142 -> 1266 | M142: =IF(K142>0,J142,0) -> 2280 | N142: =IF(K142>0,I142,0) -> 162
A143: 2025)ソフトクリーム | B143: ソフトクリーム | C143: デザート類 | D143: 443 | E143: 190491 | F143: 430 | G143: 448 | H143: =G143-F143 -> 18 | I143: =D143*H143 -> 7974 | J143: =D143*F143 -> 190490 | K143: 104.9 | L143: =D143*K143 -> 46470.7 | M143: =IF(K143>0,J143,0) -> 190490 | N143: =IF(K143>0,I143,0) -> 7974
A144: 2025)チョコバナナパフェ | B144: チョコバナナミニパフェ | C144: デザート類 | D144: 181 | E144: 95930 | F144: 530 | G144: 557 | H144: =G144-F144 -> 27 | I144: =D144*H144 -> 4887 | J144: =D144*F144 -> 95930 | K144: 112.4 | L144: =D144*K144 -> 20344.4 | M144: =IF(K144>0,J144,0) -> 95930 | N144: =IF(K144>0,I144,0) -> 4887
A145: 2025)白玉黒蜜きなこパフェ | B145: 白玉サンデー黒蜜きなこミニパフェ | C145: デザート類 | D145: 161 | E145: 85329 | F145: 530 | G145: 557 | H145: =G145-F145 -> 27 | I145: =D145*H145 -> 4347 | J145: =D145*F145 -> 85330 | K145: 132.8 | L145: =D145*K145 -> 21380.8 | M145: =IF(K145>0,J145,0) -> 85330 | N145: =IF(K145>0,I145,0) -> 4347
...
