Workbook

Sheet 前提
A1: 前提条件（黄色セルを変更すると全シートが再計算されます）
A2: 出典：予実管理表2026年9月（累計＝4〜9月・千円）／期間報（商品別・分類別）2026/4/1〜6/30 税抜
A4: 項目 | B4: 値 | C4: 単位 | D4: 出典・根拠
A5: 上期 飲食売上 実績 | B5: 54943.438 | C5: 千円 | D5: 予実管理表 累計
A6: 上期 飲食売上原価 実績 | B6: 20011.659 | C6: 千円 | D6: 予実管理表 累計
A7: 上期 飲食売上 予算 | B7: 61825.8 | C7: 千円 | D7: 予実管理表 累計
A8: 上期 飲食売上原価 予算 | B8: 20648.82 | C8: 千円 | D8: 予実管理表 累計
A9: 上期 コラボ売上 実績 | B9: 25737.219 | C9: 千円 | D9: 予実管理表 累計
A10: 上期 コラボ売上 予算 | B10: 33007 | C10: 千円 | D10: 予実管理表 累計
A11: 上期 コラボ原価 予算 | B11: 10562.24 | C11: 千円 | D11: 予実管理表 累計
A12: 上期 食事（コラボ抜き）売上 実績 | B12: 29206.219 | C12: 千円 | D12: 予実管理表 累計
A13: 上期 食事 売上 予算 | B13: 28818.8 | C13: 千円 | D13: 予実管理表 累計
A14: 上期 食事 原価 予算 | B14: 10086.58 | C14: 千円 | D14: 予実管理表 累計
A15: 期首 飲食棚卸 | B15: 1827.662 | C15: 千円 | D15: 予実管理表
A16: 上期末 飲食棚卸 | B16: 1362.454 | C16: 千円 | D16: 予実管理表
... A20: 下期の在庫増減（千円・増加は+） | B20: 0 | C20: 千円 | D20: 仮定。在庫取崩しなし（横ばい）
A22: 予算原価率 | B22: =B8/B7 -> 0.33398387 | D22: 予算原価÷予算売上
A23: 上期 原価率 実績 | B23: =B6/B5 -> 0.36422291
A24: 半期換算係数（4〜6月POS→半期千円） | B24: =B12/(B17/1000) -> 2.0710044 | C24: 倍 | D24: 上期食事売上÷4〜6月コラボ抜き売上
A25: 上期の在庫取崩し額 | B25: =B15-B16 -> 465.208 | C25: 千円 | D25: 期首−期末。原価を一時的に押し上げ

Sheet 品目別試算
A1: 品目別 出数ベース試算（2026年4〜6月 実績出数）
A2: A案＝現行改定案／B案＝強化4品を上乗せ。想定出数＝実績出数×(1＋弾力性×値上げ率)
A4: POS商品名 | B4: メニュー名 | C4: 分類 | D4: 4〜6月出数 | E4: 改定前 税抜 | F4: A案 税抜 | G4: B案 税抜 | H4: 原価単価 | I4: 値上げ率 | J4: 想定出数 | K4: 売上 改定前 | L4: 売上 改定後 | M4: 原価 改定前 | N4: 原価 改定後 | O4: 粗利増減 | P4: B案で上乗せ
A5: プレミアムロースカツカレー | B5: プレミアムロースかつカレー | C5: ご飯類 | D5: 843 | E5: 1380 | F5: 1407 | G5: 1453 | H5: 492.4 | I5: =G5/E5-1 -> 0.052898551 | J5: =D5*(1+前提!$B$18*I5) -> 829.62196 | K5: =D5*E5 -> 1163340 | L5: =J5*G5 -> 1205440.7 | M5: =D5*H5 -> 415093.2 | N5: =J5*H5 -> 408505.85 | O5: =(L5-N5)-(K5-M5) -> 48688.051 | P5: ●
A6: サーモンアボカドボウルライス | B6: サーモンアボカドベジボウル | C6: ご飯類 | D6: 338 | E6: 1280 | F6: 1325 | G6: 1325 | H6: 343.7 | I6: =G6/E6-1 -> 0.03515625 | J6: =D6*(1+前提!$B$18*I6) -> 334.43516 | K6: =D6*E6 -> 432640 | L6: =J6*G6 -> 443126.58 | M6: =D6*H6 -> 116170.6 | N6: =J6*H6 -> 114945.36 | O6: =(L6-N6)-(K6-M6) -> 11711.819
A7: バターチキンカレー | B7: バターチキンカレー | C7: ご飯類 | D7: 336 | E7: 1080 | F7: 1107 | G7: 1107 | H7: 360 | I7: =G7/E7-1 -> 0.025 | J7: =D7*(1+前提!$B$18*I7) -> 333.48 | K7: =D7*E7 -> 362880 | L7: =J7*G7 -> 369162.36 | M7: =D7*H7 -> 120960 | N7: =J7*H7 -> 120052.8 | O7: =(L7-N7)-(K7-M7) -> 7189.56
A8: ローストビーフボウルライス | B8: ローストビーフベジボウル | C8: ご飯類 | D8: 217 | E8: 1380 | F8: 1425 | G8: 1425 | H8: 576.88 | I8: =G8/E8-1 -> 0.032608696 | J8: =D8*(1+前提!$B$18*I8) -> 214.87717 | K8: =D8*E8 -> 299460 | L8: =J8*G8 -> 306199.97 | M8: =D8*H8 -> 125182.96 | N8: =J8*H8 -> 123958.34 | O8: =(L8-N8)-(K8-M8) -> 7964.5887
A9: today`sカレー | B9: today'sカレー | C9: ご飯類 | D9: 184 | E9: 980 | F9: 1007 | G9: 1007 | H9: 215.3 | I9: =G9/E9-1 -> 0.02755102 | J9: =D9*(1+前提!$B$18*I9) -> 182.47918 | K9: =D9*E9 -> 180320 | L9: =J9*G9 -> 183756.54 | M9: =D9*H9 -> 39615.2 | N9: =J9*H9 -> 39287.768 | O9: =(L9-N9)-(K9-M9) -> 3763.9697
A10: 2025)ハンバーグディッシュ | B10: ハンバーグディッシュ（デミソース） | C10: ご飯類 | D10: 89 | E10: 1580 | F10: 1625 | G10: 1625 | H10: 514 | I10: =G10/E10-1 -> 0.028481013 | J10: =D10*(1+前提!$B$18*I10) -> 88.239557 | K10: =D10*E10 -> 140620 | L10: =J10*G10 -> 143389.28 | M10: =D10*H10 -> 45746 | N10: =J10*H10 -> 45355.132 | O10: =(L10-N10)-(K10-M10) -> 3160.1478
A11: 近江牛ミンチカレー | B11: 近江牛ミンチカレー | C11: ご飯類 | D11: 86 | E11: 1480 | F11: 1507 | G11: 1507 | H11: 483.6 | I11: =G11/E11-1 -> 0.018243243 | J11: =D11*(1+前提!$B$18*I11) -> 85.529324 | K11: =D11*E11 -> 127280 | L11: =J11*G11 -> 128892.69 | M11: =D11*H11 -> 41589.6 | N11: =J11*H11 -> 41361.981 | O11: =(L11-N11)-(K11-M11) -> 1840.3105
A12: ガーリックシュリンプボウルライス | B12: ガーリックシュリンプベジボウル | C12: ご飯類 | D12: 78 | E12: 1280 | F12: 1325 | G12: 1325 | H12: 454.9 | I12: =G12/E12-1 -> 0.03515625 | J12: =D12*(1+前提!$B$18*I12) -> 77.177344 | K12: =D12*E12 -> 99840 | L12: =J12*G12 -> 102259.98 | M12: =D12*H12 -> 35482.2 | N12: =J12*H12 -> 35107.974 | O12: =(L12-N12)-(K12-M12) -> 2794.2068
A13: ガーリックステーキプレート | B13: ガーリックステーキプレート | C13: ご飯類 | D13: 70 | E13: 1280 | F13: 1325 | G13: 1325 | H13: 551.5 | I13: =G13/E13-1 -> 0.03515625 | J13: =D13*(1+前提!$B$18*I13) -> 69.261719 | K13: =D13*E13 -> 89600 | L13: =J13*G13 -> 91771.777 | M13: =D13*H13 -> 38605 | N13: =J13*H13 -> 38197.838 | O13: =(L13-N13)-(K13-M13) -> 2578.9395
A14: today`sカレーランチ | B14: today'sカレー（ランチセット） | C14: ご飯類 | D14: 79 | E14: 1030 | F14: 1057 | G14: 1057 | H14: 353.4 | I14: =G14/E14-1 -> 0.026213592 | J14: =D14*(1+前提!$B$18*I14) -> 78.378738 | K14: =D14*E14 -> 81370 | L14: =J14*G14 -> 82846.326 | M14: =D14*H14 -> 27918.6 | N14: =J14*H14 -> 27699.046 | O14: =(L14-N14)-(K14-M14) -> 1695.88
A15: ごはん単品 | B15: ごはん単品 | C15: ご飯類 | D15: 249 | E15: 280 | F15: 298 | G15: 298 | H15: 65.7 | I15: =G15/E15-1 -> 0.064285714 | J15: =D15*(1+前提!$B$18*I15) -> 244.19786 | K15: =D15*E15 -> 69720 | L15: =J15*G15 -> 72770.961 | M15: =D15*H15 -> 16359.3 | N15: =J15*H15 -> 16043.799 | O15: =(L15-N15)-(K15-M15) -> 3366.4622
A16: 2025)ポークカツディッシュ | B16: ポークカツディッシュ（デミソース） | C16: ご飯類 | D16: 40 | E16: 1580 | F16: 1625 | G16: 1625 | H16: 526.2 | I16: =G16/E16-1 -> 0.028481013 | J16: =D16*(1+前提!$B$18*I16) -> 39.658228 | K16: =D16*E16 -> 63200 | L16: =J16*G16 -> 64444.62 | M16: =D16*H16 -> 21048 | N16: =J16*H16 -> 20868.159 | O16: =(L16-N16)-(K16-M16) -> 1424.4608
A17: 大盛り | B17: ごはん大盛り | C17: ご飯類 | D17: 354 | E17: 150 | F17: 168 | G17: 200 | H17: 84 | I17: =G17/E17-1 -> 0.33333333 | J17: =D17*(1+前提!$B$18*I17) -> 318.6 | K17: =D17*E17 -> 53100 | L17: =J17*G17 -> 63720 | M17: =D17*H17 -> 29736 | N17: =J17*H17 -> 26762.4 | O17: =(L17-N17)-(K17-M17) -> 13593.6 | P17: ●
A18: ポークポパイプレート | B18: ポークポパイプレート | C18: ご飯類 | D18: 43 | E18: 1080 | F18: 1125 | G18: 1125 | H18: 434.2 | I18: =G18/E18-1 -> 0.041666667 | J18: =D18*(1+前提!$B$18*I18) -> 42.4625 | K18: =D18*E18 -> 46440 | L18: =J18*G18 -> 47770.312 | M18: =D18*H18 -> 18670.6 | N18: =J18*H18 -> 18437.217 | O18: =(L18-N18)-(K18-M18) -> 1563.695
A19: 2025)チキンディッシュ | B19: チキンディッシュ（トマトソース） | C19: ご飯類 | D19: 23 | E19: 1580 | F19: 1625 | G19: 1625 | H19: 550 | I19: =G19/E19-1 -> 0.028481013 | J19: =D19*(1+前提!$B$18*I19) -> 22.803481 | K19: =D19*E19 -> 36340 | L19: =J19*G19 -> 37055.657 | M19: =D19*H19 -> 12650 | N19: =J19*H19 -> 12541.915 | O19: =(L19-N19)-(K19-M19) -> 823.74209
A20: カルボナーラリゾット | B20: カルボナーラリゾット | C20: ご飯類 | D20: 28 | E20: 1080 | F20: 1107 | G20: 1107 | H20: 375.6 | I20: =G20/E20-1 -> 0.025 | J20: =D20*(1+前提!$B$18*I20) -> 27.79 | K20: =D20*E20 -> 30240 | L20: =J20*G20 -> 30763.53 | M20: =D20*H20 -> 10516.8 | N20: =J20*H20 -> 10437.924 | O20: =(L20-N20)-(K20-M20) -> 602.406
A21: サーロインステーキ | B21: サーロインステーキ | C21: ご飯類 | D21: 14 | E21: 1980 | F21: 2025 | G21: 2025 | H21: 810 | I21: =G21/E21-1 -> 0.022727273 | J21: =D21*(1+前提!$B$18*I21) -> 13.904545 | K21: =D21*E21 -> 27720 | L21: =J21*G21 -> 28156.705 | M21: =D21*H21 -> 11340 | N21: =J21*H21 -> 11262.682 | O21: =(L21-N21)-(K21-M21) -> 514.02273
A22: ビスクリゾット | B22: ビスクリゾット | C22: ご飯類 | D22: 24 | E22: 1080 | F22: 1107 | G22: 1107 | H22: 392.4 | I22: =G22/E22-1 -> 0.025 | J22: =D22*(1+前提!$B$18*I22) -> 23.82 | K22: =D22*E22 -> 25920 | L22: =J22*G22 -> 26368.74 | M22: =D22*H22 -> 9417.6 | N22: =J22*H22 -> 9346.968 | O22: =(L22-N22)-(K22-M22) -> 519.372
A23: 牛タングリル | B23: 仙台牛タンのグリル | C23: ご飯類 | D23: 13 | E23: 1680 | F23: 1725 | G23: 1725 | H23: 639.7 | I23: =G23/E23-1 -> 0.026785714 | J23: =D23*(1+前提!$B$18*I23) -> 12.895536 | K23: =D23*E23 -> 21840 | L23: =J23*G23 -> 22244.799 | M23: =D23*H23 -> 8316.1 | N23: =J23*H23 -> 8249.2742 | O23: =(L23-N23)-(K23-M23) -> 471.62491
A24: チキンのトマト煮 | B24: チキンのトマト煮込み | C24: ご飯類 | D24: 19 | E24: 880 | F24: 907 | G24: 907 | H24: 348.6 | I24: =G24/E24-1 -> 0.030681818 | J24: =D24*(1+前提!$B$18*I24) -> 18.825114 | K24: =D24*E24 -> 16720 | L24: =J24*G24 -> 17074.378 | M24: =D24*H24 -> 6623.4 | N24: =J24*H24 -> 6562.4346 | O24: =(L24-N24)-(K24-M24) -> 415.34345
A25: 煮込みハンバーグ | B25: 煮込みハンバーグ | C25: ご飯類 | D25: 17 | E25: 880 | F25: 907 | G25: 907 | H25: 294 | I25: =G25/E25-1 -> 0.030681818 | J25: =D25*(1+前提!$B$18*I25) -> 16.843523 | K25: =D25*E25 -> 14960 | L25: =J25*G25 -> 15277.075 | M25: =D25*H25 -> 4998 | N25: =J25*H25 -> 4951.9957 | O25: =(L25-N25)-(K25-M25) -> 363.07943
A26: ジャーマンヴルスト | B26: お肉みっちみち！ジャーマンヴルスト | C26: ご飯類 | D26: 10 | E26: 980 | F26: 1025 | G26: 1025 | H26: 371.3 | I26: =G26/E26-1 -> 0.045918367 | J26: =D26*(1+前提!$B$18*I26) -> 9.8622449 | K26: =D26*E26 -> 9800 | L26: =J26*G26 -> 10108.801 | M26: =D26*H26 -> 3713 | N26: =J26*H26 -> 3661.8515 | O26: =(L26-N26)-(K26-M26) -> 359.94949
A27: カレーリゾット | B27: カレーリゾット | C27: ご飯類 | D27: 9 | E27: 1080 | F27: 1107 | G27: 1107 | H27: 287.4 | I27: =G27/E27-1 -> 0.025 | J27: =D27*(1+前提!$B$18*I27) -> 8.9325 | K27: =D27*E27 -> 9720 | L27: =J27*G27 -> 9888.2775 | M27: =D27*H27 -> 2586.6 | N27: =J27*H27 -> 2567.2005 | O27: =(L27-N27)-(K27-M27) -> 187.677
A28: ごはんセット(味噌汁) | B28: ごはんセット（味噌汁） | C28: ご飯類 | D28: 21 | E28: 380 | F28: 398 | G28: 398 | H28: 76.7 | I28: =G28/E28-1 -> 0.047368421 | J28: =D28*(1+前提!$B$18*I28) -> 20.701579 | K28: =D28*E28 -> 7980 | L28: =J28*G28 -> 8239.2284 | M28: =D28*H28 -> 1610.7 | N28: =J28*H28 -> 1587.8111 | O28: =(L28-N28)-(K28-M28) -> 282.11732
A29: Todaysカレーランチ | B29: today'sカレー（ランチセット） | C29: ご飯類 | D29: 4 | E29: 1030 | F29: 1057 | G29: 1057 | H29: 353.4 | I29: =G29/E29-1 -> 0.026213592 | J29: =D29*(1+前提!$B$18*I29) -> 3.9685437 | K29: =D29*E29 -> 4120 | L29: =J29*G29 -> 4194.7507 | M29: =D29*H29 -> 1413.6 | N29: =J29*H29 -> 1402.4833 | O29: =(L29-N29)-(K29-M29) -> 85.86734
... A31: カンパーニュ単品 | B31: カンパーニュ単品 | C31: ご飯類 | D31: 10 | E31: 280 | F31: 298 | G31: 298 | H31: 133.1 | I31: =G31/E31-1 -> 0.064285714 | J31: =D31*(1+前提!$B$18*I31) -> 9.8071429 | K31: =D31*E31 -> 2800 | L31: =J31*G31 -> 2922.5286 | M31: =D31*H31 -> 1331 | N31: =J31*H31 -> 1305.3307 | O31: =(L31-N31)-(K31-M31) -> 148.19786
A32: ご飯大盛り | B32: ごはん大盛り | C32: ご飯類 | D32: 3 | E32: 150 | F32: 168 | G32: 200 | H32: 84 | I32: =G32/E32-1 -> 0.33333333 | J32: =D32*(1+前提!$B$18*I32) -> 2.7 | K32: =D32*E32 -> 450 | L32: =J32*G32 -> 540 | M32: =D32*H32 -> 252 | N32: =J32*H32 -> 226.8 | O32: =(L32-N32)-(K32-M32) -> 115.2 | P32: ●
A33: 2025)パイントグラス | B33: アサヒスーパードライ（パイントグラス） | C33: アルコール | D33: 416 | E33: 777 | F33: 777 | G33: 777 | H33: 284.4 | I33: =G33/E33-1 -> 0 | J33: =D33*(1+前提!$B$18*I33) -> 416 | K33: =D33*E33 -> 323232 | L33: =J33*G33 -> 323232 | M33: =D33*H33 -> 118310.4 | N33: =J33*H33 -> 118310.4 | O33: =(L33-N33)-(K33-M33) -> 0
A34: 2025)1010セット | B34: 1010セット（タパス付） | C34: アルコール | D34: 279 | E34: 1010 | F34: 1010 | G34: 1010 | H34: 312.7 | I34: =G34/E34-1 -> 0 | J34: =D34*(1+前提!$B$18*I34) -> 279 | K34: =D34*E34 -> 281790 | L34: =J34*G34 -> 281790 | M34: =D34*H34 -> 87243.3 | N34: =J34*H34 -> 87243.3 | O34: =(L34-N34)-(K34-M34) -> 0
A35: 2025)マルエフ | B35: マルエフ | C35: アルコール | D35: 327 | E35: 777 | F35: 777 | G35: 777 | H35: 307.2 | I35: =G35/E35-1 -> 0 | J35: =D35*(1+前提!$B$18*I35) -> 327 | K35: =D35*E35 -> 254079 | L35: =J35*G35 -> 254079 | M35: =D35*H35 -> 100454.4 | N35: =J35*H35 -> 100454.4 | O35: =(L35-N35)-(K35-M35) -> 0
A36: 2025)熟選ビール | B36: 熟撰 | C36: アルコール | D36: 281 | E36: 777 | F36: 777 | G36: 777 | H36: 321.7 | I36: =G36/E36-1 -> 0 | J36: =D36*(1+前提!$B$18*I36) -> 281 | K36: =D36*E36 -> 218337 | L36: =J36*G36 -> 218337 | M36: =D36*H36 -> 90397.7 | N36: =J36*H36 -> 90397.7 | O36: =(L36-N36)-(K36-M36) -> 0
A37: 2025)黒生 | B37: 黒生 | C37: アルコール | D37: 180 | E37: 777 | F37: 777 | G37: 777 | H37: 307.2 | I37: =G37/E37-1 -> 0 | J37: =D37*(1+前提!$B$18*I37) -> 180 | K37: =D37*E37 -> 139860 | L37: =J37*G37 -> 139860 | M37: =D37*H37 -> 55296 | N37: =J37*H37 -> 55296 | O37: =(L37-N37)-(K37-M37) -> 0
A38: 2025)JUGビール | B38: 1010JUGビール（800ml） | C38: アルコール | D38: 80 | E38: 930 | F38: 1203 | G38: 1203 | H38: 568.8 | I38: =G38/E38-1 -> 0.29354839 | J38: =D38*(1+前提!$B$18*I38) -> 72.954839 | K38: =D38*E38 -> 74400 | L38: =J38*G38 -> 87764.671 | M38: =D38*H38 -> 45504 | N38: =J38*H38 -> 41496.712 | O38: =(L38-N38)-(K38-M38) -> 17371.959
A39: 2025)ハイボールレギュラー | B39: ハイボール | C39: アルコール | D39: 128 | E39: 680 | F39: 698 | G39: 698 | H39: 53.5 | I39: =G39/E39-1 -> 0.026470588 | J39: =D39*(1+前提!$B$18*I39) -> 126.98353 | K39: =D39*E39 -> 87040 | L39: =J39*G39 -> 88634.504 | M39: =D39*H39 -> 6848 | N39: =J39*H39 -> 6793.6188 | O39: =(L39-N39)-(K39-M39) -> 1648.8847
A40: 2025)匠の深絞りレモンサワー | B40: 匠の深絞りレモンサワー | C40: アルコール | D40: 97 | E40: 580 | F40: 607 | G40: 607 | H40: 76.42885 | I40: =G40/E40-1 -> 0.046551724 | J40: =D40*(1+前提!$B$18*I40) -> 95.645345 | K40: =D40*E40 -> 56260 | L40: =J40*G40 -> 58056.724 | M40: =D40*H40 -> 7413.5984 | N40: =J40*H40 -> 7310.0637 | O40: =(L40-N40)-(K40-M40) -> 1900.259
A41: 2025)ピルスナーウルケル | B41: ピルスナー・ウルケル | C41: アルコール | D41: 44 | E41: 880 | F41: 898 | G41: 898 | H41: 296 | I41: =G41/E41-1 -> 0.020454545 | J41: =D41*(1+前提!$B$18*I41) -> 43.73 | K41: =D41*E41 -> 38720 | L41: =J41*G41 -> 39269.54 | M41: =D41*H41 -> 13024 | N41: =J41*H41 -> 12944.08 | O41: =(L41-N41)-(K41-M41) -> 629.46
A42: 2025)塩レモンサワー | B42: 塩レモンサワー | C42: アルコール | D42: 65 | E42: 580 | F42: 607 | G42: 607 | H42: 81.8 | I42: =G42/E42-1 -> 0.046551724 | J42: =D42*(1+前提!$B$18*I42) -> 64.092241 | K42: =D42*E42 -> 37700 | L42: =J42*G42 -> 38903.991 | M42: =D42*H42 -> 5317 | N42: =J42*H42 -> 5242.7453 | O42: =(L42-N42)-(K42-M42) -> 1278.2452
...

Sheet 効果サマリー
A1: 分類別 効果サマリー（B案・弾力性は前提シート）
A2: 4〜6月実績ベース（円）と、年間換算（千円＝4〜6月×半期換算係数×2）
A4: 分類 | B4: 売上 改定前（4〜6月） | C4: 売上増減（4〜6月） | D4: 実効値上げ率 | E4: 原価増減（4〜6月） | F4: 粗利増減（4〜6月） | G4: 理論原価率 改定前 | H4: 理論原価率 改定後 | I4: 年間 売上増減（千円） | J4: 年間 粗利増減（千円）
A5: ご飯類 | B5: =SUMIF(品目別試算!$C$5:$C$155,$A5,品目別試算!$K$5:$K$155) -> 4609488 | C5: =SUMIF(品目別試算!$C$5:$C$155,$A5,品目別試算!$L$5:$L$155)-SUMIF(品目別試算!$C$5:$C$155,$A5,品目別試算!$K$5:$K$155) -> 129968.32 | D5: =IFERROR(SUMIF(品目別試算!$C$5:$C$155,$A5,品目別試算!$G$5:$G$155)*0+(SUMIF(品目別試算!$C$5:$C$155,$A5,品目別試算!$L$5:$L$155)/SUMIF(品目別試算!$C$5:$C$155,$A5,品目別試算!$J$5:$J$155))/(SUMIF(品目別試算!$C$5:$C$155,$A5,品目別試算!$K$5:$K$155)/SUMIF(品目別試算!$C$5:$C$155,$A5,品目別試算!$D$5:$D$155))-1,0) -> 0.048399817 | E5: =SUMIF(品目別試算!$C$5:$C$155,$A5,品目別試算!$N$5:$N$155)-SUMIF(品目別試算!$C$5:$C$155,$A5,品目別試算!$M$5:$M$155) -> -20305.12 | F5: =C5-E5 -> 150273.44 | G5: =SUMIF(品目別試算!$C$5:$C$155,$A5,品目別試算!$M$5:$M$155)/SUMIF(品目別試算!$C$5:$C$155,$A5,品目別試算!$K$5:$K$155) -> 0.33320871 | H5: =SUMIF(品目別試算!$C$5:$C$155,$A5,品目別試算!$N$5:$N$155)/SUMIF(品目別試算!$C$5:$C$155,$A5,品目別試算!$L$5:$L$155) -> 0.31978698 | I5: =C5/1000*前提!$B$24*2 -> 538.32993 | J5: =F5/1000*前提!$B$24*2 -> 622.43392
A6: 麺類 | B6: =SUMIF(品目別試算!$C$5:$C$155,$A6,品目別試算!$K$5:$K$155) -> 1748440 | C6: =SUMIF(品目別試算!$C$5:$C$155,$A6,品目別試算!$L$5:$L$155)-SUMIF(品目別試算!$C$5:$C$155,$A6,品目別試算!$K$5:$K$155) -> 49568.496 | D6: =IFERROR(SUMIF(品目別試算!$C$5:$C$155,$A6,品目別試算!$G$5:$G$155)*0+(SUMIF(品目別試算!$C$5:$C$155,$A6,品目別試算!$L$5:$L$155)/SUMIF(品目別試算!$C$5:$C$155,$A6,品目別試算!$J$5:$J$155))/(SUMIF(品目別試算!$C$5:$C$155,$A6,品目別試算!$K$5:$K$155)/SUMIF(品目別試算!$C$5:$C$155,$A6,品目別試算!$D$5:$D$155))-1,0) -> 0.041418819 | E6: =SUMIF(品目別試算!$C$5:$C$155,$A6,品目別試算!$N$5:$N$155)-SUMIF(品目別試算!$C$5:$C$155,$A6,品目別試算!$M$5:$M$155) -> -6574.6918 | F6: =C6-E6 -> 56143.188 | G6: =SUMIF(品目別試算!$C$5:$C$155,$A6,品目別試算!$M$5:$M$155)/SUMIF(品目別試算!$C$5:$C$155,$A6,品目別試算!$K$5:$K$155) -> 0.29677192 | H6: =SUMIF(品目別試算!$C$5:$C$155,$A6,品目別試算!$N$5:$N$155)/SUMIF(品目別試算!$C$5:$C$155,$A6,品目別試算!$L$5:$L$155) -> 0.2849337 | I6: =C6/1000*前提!$B$24*2 -> 205.31314 | J6: =F6/1000*前提!$B$24*2 -> 232.54557
A7: 一品料理 | B7: =SUMIF(品目別試算!$C$5:$C$155,$A7,品目別試算!$K$5:$K$155) -> 2197540 | C7: =SUMIF(品目別試算!$C$5:$C$155,$A7,品目別試算!$L$5:$L$155)-SUMIF(品目別試算!$C$5:$C$155,$A7,品目別試算!$K$5:$K$155) -> 66077.973 | D7: =IFERROR(SUMIF(品目別試算!$C$5:$C$155,$A7,品目別試算!$G$5:$G$155)*0+(SUMIF(品目別試算!$C$5:$C$155,$A7,品目別試算!$L$5:$L$155)/SUMIF(品目別試算!$C$5:$C$155,$A7,品目別試算!$J$5:$J$155))/(SUMIF(品目別試算!$C$5:$C$155,$A7,品目別試算!$K$5:$K$155)/SUMIF(品目別試算!$C$5:$C$155,$A7,品目別試算!$D$5:$D$155))-1,0) -> 0.045642284 | E7: =SUMIF(品目別試算!$C$5:$C$155,$A7,品目別試算!$N$5:$N$155)-SUMIF(品目別試算!$C$5:$C$155,$A7,品目別試算!$M$5:$M$155) -> -9617.4677 | F7: =C7-E7 -> 75695.44 | G7: =SUMIF(品目別試算!$C$5:$C$155,$A7,品目別試算!$M$5:$M$155)/SUMIF(品目別試算!$C$5:$C$155,$A7,品目別試算!$K$5:$K$155) -> 0.33622269 | H7: =SUMIF(品目別試算!$C$5:$C$155,$A7,品目別試算!$N$5:$N$155)/SUMIF(品目別試算!$C$5:$C$155,$A7,品目別試算!$L$5:$L$155) -> 0.32215919 | I7: =C7/1000*前提!$B$24*2 -> 273.69554 | J7: =F7/1000*前提!$B$24*2 -> 313.53117
A8: アルコール | B8: =SUMIF(品目別試算!$C$5:$C$155,$A8,品目別試算!$K$5:$K$155) -> 1950538 | C8: =SUMIF(品目別試算!$C$5:$C$155,$A8,品目別試算!$L$5:$L$155)-SUMIF(品目別試算!$C$5:$C$155,$A8,品目別試算!$K$5:$K$155) -> 31271.184 | D8: =IFERROR(SUMIF(品目別試算!$C$5:$C$155,$A8,品目別試算!$G$5:$G$155)*0+(SUMIF(品目別試算!$C$5:$C$155,$A8,品目別試算!$L$5:$L$155)/SUMIF(品目別試算!$C$5:$C$155,$A8,品目別試算!$J$5:$J$155))/(SUMIF(品目別試算!$C$5:$C$155,$A8,品目別試算!$K$5:$K$155)/SUMIF(品目別試算!$C$5:$C$155,$A8,品目別試算!$D$5:$D$155))-1,0) -> 0.023840993 | E8: =SUMIF(品目別試算!$C$5:$C$155,$A8,品目別試算!$N$5:$N$155)-SUMIF(品目別試算!$C$5:$C$155,$A8,品目別試算!$M$5:$M$155) -> -5663.161 | F8: =C8-E8 -> 36934.345 | G8: =SUMIF(品目別試算!$C$5:$C$155,$A8,品目別試算!$M$5:$M$155)/SUMIF(品目別試算!$C$5:$C$155,$A8,品目別試算!$K$5:$K$155) -> 0.32745703 | H8: =SUMIF(品目別試算!$C$5:$C$155,$A8,品目別試算!$N$5:$N$155)/SUMIF(品目別試算!$C$5:$C$155,$A8,品目別試算!$L$5:$L$155) -> 0.31943247 | I8: =C8/1000*前提!$B$24*2 -> 129.52552 | J8: =F8/1000*前提!$B$24*2 -> 152.98238
A9: ソフトドリンク | B9: =SUMIF(品目別試算!$C$5:$C$155,$A9,品目別試算!$K$5:$K$155) -> 1494060 | C9: =SUMIF(品目別試算!$C$5:$C$155,$A9,品目別試算!$L$5:$L$155)-SUMIF(品目別試算!$C$5:$C$155,$A9,品目別試算!$K$5:$K$155) -> 55141.208 | D9: =IFERROR(SUMIF(品目別試算!$C$5:$C$155,$A9,品目別試算!$G$5:$G$155)*0+(SUMIF(品目別試算!$C$5:$C$155,$A9,品目別試算!$L$5:$L$155)/SUMIF(品目別試算!$C$5:$C$155,$A9,品目別試算!$J$5:$J$155))/(SUMIF(品目別試算!$C$5:$C$155,$A9,品目別試算!$K$5:$K$155)/SUMIF(品目別試算!$C$5:$C$155,$A9,品目別試算!$D$5:$D$155))-1,0) -> 0.055594977 | E9: =SUMIF(品目別試算!$C$5:$C$155,$A9,品目別試算!$N$5:$N$155)-SUMIF(品目別試算!$C$5:$C$155,$A9,品目別試算!$M$5:$M$155) -> -5150.3954 | F9: =C9-E9 -> 60291.603 | G9: =SUMIF(品目別試算!$C$5:$C$155,$A9,品目別試算!$M$5:$M$155)/SUMIF(品目別試算!$C$5:$C$155,$A9,品目別試算!$K$5:$K$155) -> 0.21774765 | H9: =SUMIF(品目別試算!$C$5:$C$155,$A9,品目別試算!$N$5:$N$155)/SUMIF(品目別試算!$C$5:$C$155,$A9,品目別試算!$L$5:$L$155) -> 0.20667274 | I9: =C9/1000*前提!$B$24*2 -> 228.39537 | J9: =F9/1000*前提!$B$24*2 -> 249.72835
A10: デザート類 | B10: =SUMIF(品目別試算!$C$5:$C$155,$A10,品目別試算!$K$5:$K$155) -> 587330 | C10: =SUMIF(品目別試算!$C$5:$C$155,$A10,品目別試算!$L$5:$L$155)-SUMIF(品目別試算!$C$5:$C$155,$A10,品目別試算!$K$5:$K$155) -> 21361.315 | D10: =IFERROR(SUMIF(品目別試算!$C$5:$C$155,$A10,品目別試算!$G$5:$G$155)*0+(SUMIF(品目別試算!$C$5:$C$155,$A10,品目別試算!$L$5:$L$155)/SUMIF(品目別試算!$C$5:$C$155,$A10,品目別試算!$J$5:$J$155))/(SUMIF(品目別試算!$C$5:$C$155,$A10,品目別試算!$K$5:$K$155)/SUMIF(品目別試算!$C$5:$C$155,$A10,品目別試算!$D$5:$D$155))-1,0) -> 0.053104032 | E10: =SUMIF(品目別試算!$C$5:$C$155,$A10,品目別試算!$N$5:$N$155)-SUMIF(品目別試算!$C$5:$C$155,$A10,品目別試算!$M$5:$M$155) -> -2176.6538 | F10: =C10-E10 -> 23537.969 | G10: =SUMIF(品目別試算!$C$5:$C$155,$A10,品目別試算!$M$5:$M$155)/SUMIF(品目別試算!$C$5:$C$155,$A10,品目別試算!$K$5:$K$155) -> 0.23636218 | H10: =SUMIF(品目別試算!$C$5:$C$155,$A10,品目別試算!$N$5:$N$155)/SUMIF(品目別試算!$C$5:$C$155,$A10,品目別試算!$L$5:$L$155) -> 0.22449137 | I10: =C10/1000*前提!$B$24*2 -> 88.478755 | J10: =F10/1000*前提!$B$24*2 -> 97.494474
A11: 合計 | B11: =SUM(B5:B10) -> 12587396 | C11: =SUM(C5:C10) -> 353388.5 | D11: =C11/B11 -> 0.02807479 | E11: =SUM(E5:E10) -> -49487.49 | F11: =SUM(F5:F10) -> 402875.99 | G11: =SUM(品目別試算!$M$5:$M$155)/SUM(品目別試算!$K$5:$K$155) -> 0.30955889 | H11: =SUM(品目別試算!$N$5:$N$155)/SUM(品目別試算!$L$5:$L$155) -> 0.29728127 | I11: =SUM(I5:I10) -> 1463.7383 | J11: =SUM(J5:J10) -> 1668.7159
A13: コラボ抜き売上全体に対する実効値上げ率（出数変化なしの場合） | D13: =SUMPRODUCT(品目別試算!$D$5:$D$155,品目別試算!$G$5:$G$155-品目別試算!$E$5:$E$155)/前提!B17 -> 0.036881059
A14: ※実効値上げ率（D列）は1品あたり平均単価の上昇率。D13は据え置き商品・価格表外商品も含むコラボ抜き売上全体に対する率。

Sheet 原価率プラン
A1: 飲食原価率 改善プラン（下期・通期）
A2: 単位：千円。下期は上期と同水準の売上・出数を前提（前提シートで変更可）
A4: ステップ | B4: 売上 | C4: 原価 | D4: 原価率 | E4: 改善幅 | F4: 根拠
A5: 上期 実績 | B5: =前提!B5 -> 54943.438 | C5: =前提!B6 -> 20011.659 | D5: =C5/B5 -> 0.36422291 | F5: 予実管理表
A6: 下期ベース（在庫取崩しなし） | B6: =前提!B5*前提!B19 -> 54943.438 | C6: =(前提!B6-前提!$B$25)*前提!B19-前提!B20 -> 19546.451 | D6: =C6/B6 -> 0.35575588 | E6: =(D6-D5)*100 -> -0.84670348 | F6: 上期の在庫取崩しは一時要因として除外
A7: ＋値上げ（A案＋B案、弾力性反映） | B7: =B6+効果サマリー!C11/1000*前提!$B$24 -> 55675.307 | C7: =C6+効果サマリー!E11/1000*前提!$B$24 -> 19443.962 | D7: =C7/B7 -> 0.34923853 | E7: =(D7-D6)*100 -> -0.65173516 | F7: 品目別試算（出数ベース）
A8: ＋原価コントロール（必要額） | B8: =B7 -> 55675.307 | C8: =B7*前提!$B$22 -> 18594.655 | D8: =C8/B8 -> 0.33398387 | E8: =(D8-D7)*100 -> -1.5254655 | F8: 下期を予算原価率に収めるための原価
A10: 原価コントロール 必要削減額（下期） | B10: =C7-C8 -> 849.30761 | C10: =B10/C7 -> 0.04367976 | F10: 下期原価に対する削減率
A12: 通期 着地（下期を予算原価率で着地） | B12: =B5+B8 -> 110618.75 | C12: =C5+C8 -> 38606.314 | D12: =C12/B12 -> 0.34900336 | E12: =(D12-前提!$B$22)*100 -> 1.5019488 | F12: 予算原価率との差
A13: 通期を予算原価率に収めるための下期原価上限 | B13: =B8 -> 55675.307 | C13: =前提!$B$22*(B5+B8)-C5 -> 16933.218 | D13: =C13/B13 -> 0.30414233 | F13: 上期の超過分を下期で取り戻す場合
A14: → 追加で必要な原価圧縮（上期超過分） | B14: =C8-C13 -> 1661.4369 | F14: ＝上期の原価超過額にほぼ等しい
A16: 参考：値上げだけで下期を予算原価率に収める場合の必要値上げ率（GM一律） | D16: =(C6/前提!$B$22-B6)/前提!B12 -> 0.12263472 | F16: 出数変化を考慮しない概算

Sheet 要因分解
A1: 上期 原価率超過の要因分解（試算）
A2: 予算の区分別原価率（コラボ32.0%・食事35.0%）を実績の売上構成に当てはめて分解
A4: 要因 | B4: 原価額への影響（千円） | C4: 原価率への影響 | D4: 考え方
A5: 予算原価率 | C5: =前提!$B$22 -> 0.33398387 | D5: 予算原価÷予算売上
A6: ① コラボ不振による売上構成の変化 | B6: =前提!B9*前提!B11/前提!B10+前提!B12*前提!B14/前提!B13-前提!$B$22*前提!B5 -> 107.86463 | C6: =B6/前提!B5*100 -> 0.19631941 | D6: 予算の区分別原価率×実績売上 − 予算原価率×実績売上
A7: ② 在庫取崩し（一時要因） | B7: =前提!$B$25 -> 465.208 | C7: =B7/前提!B5*100 -> 0.84670348 | D7: 期首棚卸−期末棚卸
A8: ③ 原価圧迫・ロス等（コラボ食材ロス含む） | B8: =前提!B6-前提!$B$22*前提!B5-B6-B7 -> 1088.3643 | C8: =B8/前提!B5*100 -> 1.9808813 | D8: 残差
A9: 上期 実績原価率 | B9: =前提!B6-前提!$B$22*前提!B5 -> 1661.4369 | C9: =前提!$B$23 -> 0.36422291 | D9: B列合計＝予算原価率に対する原価超過額
A11: ※コラボ原価が売上に比例する前提。特典・最低ロットなど売上に連動しないコラボ原価がある場合、①の比重は大きくなり③は小さくなります。

Sheet 競合価格
A1: 周辺飲食店・温浴施設の価格（2026年10月 Web調査）
A2: ※検索結果ベースの情報です。最新価格は各店の公式情報で確認してください
A4: 区分 | B4: 店名 | C4: 品目 | D4: 税込価格 | E4: 出典 | F4: 情報時期
A5: 神田周辺 | B5: 立呑み神田屋 神田駅前店 | C5: 生ビール（ジョッキ） | D5: 429 | E5: tabelog.com | F5: 不明
A6: 神田周辺 | B6: 日高屋 | C6: 生ビール中 | D6: 390 | E6: gourmet.watch.impress.co.jp | F6: 2025夏
A7: 神田周辺 | B7: 磯丸水産 | C7: ハイボール・レモンサワー | D7: 499 | E7: weekly.ascii.jp | F7: 2026-08
A8: 神田周辺 | B8: 鳥貴族 | C8: 全品均一（生ビール・唐揚げ含む） | D8: 410 | E8: news.nissyoku.co.jp | F8: 2026-10改定
A9: 神田周辺 | B9: 日乃屋カレー 神田 | C9: 名物カツカレー | D9: 780 | E9: kanda-curry.com | F9: 2026頃
A10: 神田周辺 | B10: 新潟タレカツ 神田今川橋店 | C10: カツカレー | D10: 1180 | E10: kanda-curry.com | F10: 2026頃
A11: 神田周辺 | B11: いっぺこっぺ 神田小川町店 | C11: 上ロースカツカレー | D11: 1800 | E11: kanda-curry.com | F11: 2026頃
A12: 神田周辺 | B12: キッチンきらく | C12: カツカレー | D12: 1940 | E12: kanda-curry.com | F12: 2026頃
A13: 神田周辺 | B13: 神保町オオドリー（カレーGP2025優勝） | C13: キーマカレー | D13: 1650 | E13: san-tatsu.jp | F13: 2026-10
A14: チェーン | B14: 丸亀製麺 | C14: 釜玉うどん並 | D14: 550 | E14: gourmet.watch.impress.co.jp | F14: 2026-01改定
A15: 温浴施設 | B15: スパ ラクーア | C15: カレーライス／牛すじ肉うどん | D15: 1100 | E15: sp.jorudan.co.jp | F15: 2026-05
A16: 温浴施設 | B16: スパ ラクーア | C16: トルティーヤチップス | D16: 550 | E16: sp.jorudan.co.jp | F16: 2026-05
... A23: 温浴施設 | B23: 萩の湯（鶯谷） | C23: 生ビール中 | D23: 500 | E23: enjoytokyo.jp | F23: 2024頃
A25: マクロ指標：外食CPI 2025年度 前年比+4.2%（総務省）／食品値上げ 2026年累計20,187品目（9/30時点、帝国データバンク）／ビール酒税 2026年10月 350mlあたり9.1円減税／米価 2026年8月 5kg平均3,191円（前年比約1割安）
